Workbook

Sheet Bud27 vs Proj26
B1: Note: All figures are fictional and for illustration only.
B3: XYZ Company Ltd.
B4: OH Budget Summary FY'27 & FY'26
B6: Particulars | C6: YTD Act Dec'25 | D6: Jan'26 to Mar'26 Forecast | E6: Full Year Projection FY:25-26 | F6: Budget FY:26-27 | G6: Budget 25-26 | H6: Growth over FY26 Proj % | I6: Growth over Budget % | J6: Remarks
B7: Advertisement and Sales Promotion | C7: =SUMIFS('Budget-27'!I:I,'Budget-27'!A:A,'Bud27 vs Proj26'!B7) -> 39000 | D7: =SUMIFS('Budget-27'!J:J,'Budget-27'!A:A,'Bud27 vs Proj26'!B7) -> 24000 | E7: =C7+D7 -> 63000 | F7: =SUMIFS('Budget-27'!L:L,'Budget-27'!A:A,'Bud27 vs Proj26'!B7) -> 61000 | G7: =SUMIFS('Budget-27'!G:G,'Budget-27'!A:A,'Bud27 vs Proj26'!B7) -> 50000 | H7: =(F7-E7)/E7 -> -0.031746032 | I7: =(F7-G7)/G7 -> 0.22
B8: Communication Costs | C8: =SUMIFS('Budget-27'!I:I,'Budget-27'!A:A,'Bud27 vs Proj26'!B8) -> 20000 | D8: =SUMIFS('Budget-27'!J:J,'Budget-27'!A:A,'Bud27 vs Proj26'!B8) -> 18000 | E8: =C8+D8 -> 38000 | F8: =SUMIFS('Budget-27'!L:L,'Budget-27'!A:A,'Bud27 vs Proj26'!B8) -> 30000 | G8: =SUMIFS('Budget-27'!G:G,'Budget-27'!A:A,'Bud27 vs Proj26'!B8) -> 30000 | H8: =(F8-E8)/E8 -> -0.21052632 | I8: =(F8-G8)/G8 -> 0
B9: ECL/Bad Debts | C9: =SUMIFS('Budget-27'!I:I,'Budget-27'!A:A,'Bud27 vs Proj26'!B9) -> 140000 | D9: =SUMIFS('Budget-27'!J:J,'Budget-27'!A:A,'Bud27 vs Proj26'!B9) -> -140000 | E9: =C9+D9 -> 0 | F9: =SUMIFS('Budget-27'!L:L,'Budget-27'!A:A,'Bud27 vs Proj26'!B9) -> 0 | G9: =SUMIFS('Budget-27'!G:G,'Budget-27'!A:A,'Bud27 vs Proj26'!B9) -> 0 | H9: =IFERROR((F9-E9)/E9,0) -> 0
B10: Insurance | C10: =SUMIFS('Budget-27'!I:I,'Budget-27'!A:A,'Bud27 vs Proj26'!B10) -> 25000 | D10: =SUMIFS('Budget-27'!J:J,'Budget-27'!A:A,'Bud27 vs Proj26'!B10) -> 5000 | E10: =C10+D10 -> 30000 | F10: =SUMIFS('Budget-27'!L:L,'Budget-27'!A:A,'Bud27 vs Proj26'!B10) -> 33000 | G10: =SUMIFS('Budget-27'!G:G,'Budget-27'!A:A,'Bud27 vs Proj26'!B10) -> 30000 | H10: =(F10-E10)/E10 -> 0.1 | I10: =(F10-G10)/G10 -> 0.1
B11: Legal & Professional Fees | C11: =SUMIFS('Budget-27'!I:I,'Budget-27'!A:A,'Bud27 vs Proj26'!B11) -> 106000 | D11: =SUMIFS('Budget-27'!J:J,'Budget-27'!A:A,'Bud27 vs Proj26'!B11) -> 24000 | E11: =C11+D11 -> 130000 | F11: =SUMIFS('Budget-27'!L:L,'Budget-27'!A:A,'Bud27 vs Proj26'!B11) -> 140000 | G11: =SUMIFS('Budget-27'!G:G,'Budget-27'!A:A,'Bud27 vs Proj26'!B11) -> 210000 | H11: =(F11-E11)/E11 -> 0.076923077 | I11: =(F11-G11)/G11 -> -0.33333333
B12: Personnel cost | C12: =SUMIFS('Budget-27'!I:I,'Budget-27'!A:A,'Bud27 vs Proj26'!B12) -> 346000 | D12: =SUMIFS('Budget-27'!J:J,'Budget-27'!A:A,'Bud27 vs Proj26'!B12) -> 111000 | E12: =C12+D12 -> 457000 | F12: =SUMIFS('Budget-27'!L:L,'Budget-27'!A:A,'Bud27 vs Proj26'!B12) -> 440000 | G12: =SUMIFS('Budget-27'!G:G,'Budget-27'!A:A,'Bud27 vs Proj26'!B12) -> 350000 | H12: =(F12-E12)/E12 -> -0.037199125 | I12: =(F12-G12)/G12 -> 0.25714286
B13: Operating & Other Expenses | C13: =SUMIFS('Budget-27'!I:I,'Budget-27'!A:A,'Bud27 vs Proj26'!B13) -> 95000 | D13: =SUMIFS('Budget-27'!J:J,'Budget-27'!A:A,'Bud27 vs Proj26'!B13) -> 39000 | E13: =C13+D13 -> 134000 | F13: =SUMIFS('Budget-27'!L:L,'Budget-27'!A:A,'Bud27 vs Proj26'!B13) -> 200000 | G13: =SUMIFS('Budget-27'!G:G,'Budget-27'!A:A,'Bud27 vs Proj26'!B13) -> 170000 | H13: =(F13-E13)/E13 -> 0.49253731 | I13: =(F13-G13)/G13 -> 0.17647059
B14: Product Registration | C14: =SUMIFS('Budget-27'!I:I,'Budget-27'!A:A,'Bud27 vs Proj26'!B14) -> 10000 | D14: =SUMIFS('Budget-27'!J:J,'Budget-27'!A:A,'Bud27 vs Proj26'!B14) -> 10000 | E14: =C14+D14 -> 20000 | F14: =SUMIFS('Budget-27'!L:L,'Budget-27'!A:A,'Bud27 vs Proj26'!B14) -> 5000 | G14: =SUMIFS('Budget-27'!G:G,'Budget-27'!A:A,'Bud27 vs Proj26'!B14) -> 30000 | H14: =(F14-E14)/E14 -> -0.75 | I14: =(F14-G14)/G14 -> -0.83333333
B15: Travel & Conveyance | C15: =SUMIFS('Budget-27'!I:I,'Budget-27'!A:A,'Bud27 vs Proj26'!B15) -> 30000 | D15: =SUMIFS('Budget-27'!J:J,'Budget-27'!A:A,'Bud27 vs Proj26'!B15) -> 30000 | E15: =C15+D15 -> 60000 | F15: =SUMIFS('Budget-27'!L:L,'Budget-27'!A:A,'Bud27 vs Proj26'!B15) -> 15000 | G15: =SUMIFS('Budget-27'!G:G,'Budget-27'!A:A,'Bud27 vs Proj26'!B15) -> 38000 | H15: =(F15-E15)/E15 -> -0.75 | I15: =(F15-G15)/G15 -> -0.60526316
B16: Total | C16: =SUM(C7:C15) -> 811000 | D16: =SUM(D7:D15) -> 121000 | E16: =SUM(E7:E15) -> 932000 | F16: =SUM(F7:F15) -> 924000 | G16: =SUM(G7:G15) -> 908000 | H16: =(F16-E16)/E16 -> -0.008583691 | I16: =(F16-G16)/G16 -> 0.017621145

Sheet Budget-27
A1: ='Bud27 vs Proj26'!B1 -> Note: All figures are fictional and for illustration only.
A3: Budget & Monthly Forecast | F3: =SUBTOTAL(9,F6:F52) -> 728000 | G3: =SUBTOTAL(9,G6:G52) -> 908000 | I3: =SUBTOTAL(9,I6:I52) -> 811000 | J3: =SUBTOTAL(9,J6:J52) -> 121000 | K3: =SUBTOTAL(9,K6:K52) -> 932000 | L3: =SUBTOTAL(9,L6:L52) -> 924000 | M3: Q1 | N3: Q1 | O3: Q1 | P3: Q2 | Q3: Q2 | R3: Q2 | S3: Q3 | T3: Q3 | U3: Q3 | V3: Q4 | W3: Q4 | X3: Q4
F4: Rupi | M4: 2026.01 | N4: 2026.02 | O4: 2026.03 | P4: 2026.04 | Q4: 2026.05 | R4: 2026.06 | S4: 2026.07 | T4: 2026.08 | U4: 2026.09 | V4: 2026.1 | W4: 2026.11 | X4: 2026.12
A5: Group | B5: G/L account | C5: G/L description | D5: Description | E5: Cost Center | F5: PY Act OH 2024-25 | G5: Budget 2025-26 | H5: PY YTD Act Dec 2024 | I5: YTD Act Dec 2025 | J5: Jan'26 to Mar'26 Forecast | K5: Full Year Closing FY: 25-26 | L5: Budget 2026-27 | M5: 46135 | N5: 46165 | O5: 46196 | P5: 46226 | Q5: 46257 | R5: 46288 | S5: 46318 | T5: 46349 | U5: 46379 | V5: 46410 | W5: 46441 | X5: 46469
A6: Advertisement and Sales Promotion | C6: Product Samples | F6: 5000 | G6: 10000 | H6: 4000 | I6: 6000 | J6: 4000 | K6: 10000 | L6: 10000 | M6: =$L$6/12 -> 833.33333 | N6: =$L$6/12 -> 833.33333 | O6: =$L$6/12 -> 833.33333 | P6: =$L$6/12 -> 833.33333 | Q6: =$L$6/12 -> 833.33333 | R6: =$L$6/12 -> 833.33333 | S6: =$L$6/12 -> 833.33333 | T6: =$L$6/12 -> 833.33333 | ... X6: =$L$6/12 -> 833.33333
A7: Advertisement and Sales Promotion | C7: Field Reimbursement | F7: 0 | G7: 10000 | H7: 0 | I7: 3000 | J7: 8000 | K7: 11000 | L7: 10000 | M7: =$L$7/12 -> 833.33333 | N7: =$L$7/12 -> 833.33333 | O7: =$L$7/12 -> 833.33333 | P7: =$L$7/12 -> 833.33333 | Q7: =$L$7/12 -> 833.33333 | R7: =$L$7/12 -> 833.33333 | S7: =$L$7/12 -> 833.33333 | T7: =$L$7/12 -> 833.33333 | ... X7: =$L$7/12 -> 833.33333
A8: Advertisement and Sales Promotion | C8: Sales Promotion | F8: 15000 | G8: 0 | H8: 4000 | I8: 9000 | J8: 0 | K8: 9000 | L8: 0 | M8: =$L$8/12 -> 0 | N8: =$L$8/12 -> 0 | O8: =$L$8/12 -> 0 | P8: =$L$8/12 -> 0 | Q8: =$L$8/12 -> 0 | R8: =$L$8/12 -> 0 | S8: =$L$8/12 -> 0 | T8: =$L$8/12 -> 0 | ... X8: =$L$8/12 -> 0
A9: Advertisement and Sales Promotion | C9: Social Media | F9: 0 | G9: 0 | H9: 0 | I9: 2000 | J9: 0 | K9: 2000 | L9: 6000 | M9: =$L$9/12 -> 500 | N9: =$L$9/12 -> 500 | O9: =$L$9/12 -> 500 | P9: =$L$9/12 -> 500 | Q9: =$L$9/12 -> 500 | R9: =$L$9/12 -> 500 | S9: =$L$9/12 -> 500 | T9: =$L$9/12 -> 500 | ... X9: =$L$9/12 -> 500
A10: Advertisement and Sales Promotion | C10: Regional Meetings | F10: 8000 | G10: 10000 | H10: 6000 | I10: 1000 | J10: 1000 | K10: 2000 | L10: 4000 | M10: =$L10/12 -> 333.33333 | N10: =$L10/12 -> 333.33333 | O10: =$L10/12 -> 333.33333 | P10: =$L10/12 -> 333.33333 | Q10: =$L10/12 -> 333.33333 | R10: =$L10/12 -> 333.33333 | S10: =$L10/12 -> 333.33333 | T10: =$L10/12 -> 333.33333 | ... X10: =$L10/12 -> 333.33333
A11: Advertisement and Sales Promotion | C11: Customer Events | F11: 9000 | G11: 10000 | H11: 7000 | I11: 7000 | J11: 4000 | K11: 11000 | L11: 10000 | M11: =$L11/12 -> 833.33333 | N11: =$L11/12 -> 833.33333 | O11: =$L11/12 -> 833.33333 | P11: =$L11/12 -> 833.33333 | Q11: =$L11/12 -> 833.33333 | R11: =$L11/12 -> 833.33333 | S11: =$L11/12 -> 833.33333 | T11: =$L11/12 -> 833.33333 | ... X11: =$L11/12 -> 833.33333
A12: Advertisement and Sales Promotion | C12: Promotional Giveaways | F12: 0 | G12: 0 | H12: 0 | I12: 1000 | J12: 0 | K12: 1000 | L12: 4000 | M12: =$L12/12 -> 333.33333 | N12: =$L12/12 -> 333.33333 | O12: =$L12/12 -> 333.33333 | P12: =$L12/12 -> 333.33333 | Q12: =$L12/12 -> 333.33333 | R12: =$L12/12 -> 333.33333 | S12: =$L12/12 -> 333.33333 | T12: =$L12/12 -> 333.33333 | ... X12: =$L12/12 -> 333.33333
A13: Advertisement and Sales Promotion | C13: Printed Collateral | F13: 0 | G13: 0 | H13: 0 | I13: 5000 | J13: 0 | K13: 5000 | L13: 7000 | M13: =$L13/12 -> 583.33333 | N13: =$L13/12 -> 583.33333 | O13: =$L13/12 -> 583.33333 | P13: =$L13/12 -> 583.33333 | Q13: =$L13/12 -> 583.33333 | R13: =$L13/12 -> 583.33333 | S13: =$L13/12 -> 583.33333 | T13: =$L13/12 -> 583.33333 | ... X13: =$L13/12 -> 583.33333
A14: Advertisement and Sales Promotion | C14: Advertising | F14: 4000 | G14: 10000 | H14: 6000 | I14: 5000 | J14: 7000 | K14: 12000 | L14: 10000 | M14: =$L14/12 -> 833.33333 | N14: =$L14/12 -> 833.33333 | O14: =$L14/12 -> 833.33333 | P14: =$L14/12 -> 833.33333 | Q14: =$L14/12 -> 833.33333 | R14: =$L14/12 -> 833.33333 | S14: =$L14/12 -> 833.33333 | T14: =$L14/12 -> 833.33333 | ... X14: =$L14/12 -> 833.33333
A15: Communication Costs | C15: Courier & Postage | F15: 9000 | G15: 10000 | H15: 9000 | I15: 6000 | J15: 7000 | K15: 13000 | L15: 10000 | M15: =$L15/12 -> 833.33333 | N15: =$L15/12 -> 833.33333 | O15: =$L15/12 -> 833.33333 | P15: =$L15/12 -> 833.33333 | Q15: =$L15/12 -> 833.33333 | R15: =$L15/12 -> 833.33333 | S15: =$L15/12 -> 833.33333 | T15: =$L15/12 -> 833.33333 | ... X15: =$L15/12 -> 833.33333
A16: Communication Costs | C16: Internet Charges | F16: 2000 | G16: 10000 | H16: 8000 | I16: 9000 | J16: 2000 | K16: 11000 | L16: 10000 | M16: =$L16/12 -> 833.33333 | N16: =$L16/12 -> 833.33333 | O16: =$L16/12 -> 833.33333 | P16: =$L16/12 -> 833.33333 | Q16: =$L16/12 -> 833.33333 | R16: =$L16/12 -> 833.33333 | S16: =$L16/12 -> 833.33333 | T16: =$L16/12 -> 833.33333 | ... X16: =$L16/12 -> 833.33333
A17: Communication Costs | C17: Telephone Expenses | F17: 9000 | G17: 10000 | H17: 4000 | I17: 5000 | J17: 9000 | K17: 14000 | L17: 10000 | M17: =$L17/12 -> 833.33333 | N17: =$L17/12 -> 833.33333 | O17: =$L17/12 -> 833.33333 | P17: =$L17/12 -> 833.33333 | Q17: =$L17/12 -> 833.33333 | R17: =$L17/12 -> 833.33333 | S17: =$L17/12 -> 833.33333 | T17: =$L17/12 -> 833.33333 | ... X17: =$L17/12 -> 833.33333
A18: ECL/Bad Debts | C18: Expected Credit Loss | F18: 60000 | G18: 0 | H18: 40000 | I18: 140000 | J18: -140000 | K18: 0 | L18: 0 | M18: =$L18/12 -> 0 | N18: =$L18/12 -> 0 | O18: =$L18/12 -> 0 | P18: =$L18/12 -> 0 | Q18: =$L18/12 -> 0 | R18: =$L18/12 -> 0 | S18: =$L18/12 -> 0 | T18: =$L18/12 -> 0 | ... X18: =$L18/12 -> 0
A19: Insurance | C19: Credit Insurance | F19: 4000 | G19: 0 | H19: 9000 | I19: 5000 | J19: 0 | K19: 5000 | L19: 3000 | M19: =$L19/12 -> 250 | N19: =$L19/12 -> 250 | O19: =$L19/12 -> 250 | P19: =$L19/12 -> 250 | Q19: =$L19/12 -> 250 | R19: =$L19/12 -> 250 | S19: =$L19/12 -> 250 | T19: =$L19/12 -> 250 | ... X19: =$L19/12 -> 250
A20: Insurance | C20: Insurance | F20: 20000 | G20: 30000 | H20: 10000 | I20: 20000 | J20: 5000 | K20: 25000 | L20: 30000 | M20: =$L20/12 -> 2500 | N20: =$L20/12 -> 2500 | O20: =$L20/12 -> 2500 | P20: =$L20/12 -> 2500 | Q20: =$L20/12 -> 2500 | R20: =$L20/12 -> 2500 | S20: =$L20/12 -> 2500 | T20: =$L20/12 -> 2500 | ... X20: =$L20/12 -> 2500
A21: Legal & Professional Fees | C21: Other Professional Services | F21: 8000 | G21: 30000 | H21: 9000 | I21: 5000 | J21: 4000 | K21: 9000 | L21: 10000 | M21: =$L21/12 -> 833.33333 | N21: =$L21/12 -> 833.33333 | O21: =$L21/12 -> 833.33333 | P21: =$L21/12 -> 833.33333 | Q21: =$L21/12 -> 833.33333 | R21: =$L21/12 -> 833.33333 | S21: =$L21/12 -> 833.33333 | T21: =$L21/12 -> 833.33333 | ... X21: =$L21/12 -> 833.33333
... A33: Operating & Other Expenses | C33: Printing | F33: 8000 | G33: 20000 | H33: 7000 | I33: 10000 | J33: 4000 | K33: 14000 | L33: 20000 | M33: =$L33/12 -> 1666.6667 | N33: =$L33/12 -> 1666.6667 | O33: =$L33/12 -> 1666.6667 | P33: =$L33/12 -> 1666.6667 | Q33: =$L33/12 -> 1666.6667 | R33: =$L33/12 -> 1666.6667 | S33: =$L33/12 -> 1666.6667 | T33: =$L33/12 -> 1666.6667 | ... X33: =$L33/12 -> 1666.6667
A34: Operating & Other Expenses | C34: Maintenance Supplies | F34: 3000 | G34: 20000 | H34: 2000 | I34: 5000 | J34: 4000 | K34: 9000 | L34: 20000 | M34: =$L$34/12 -> 1666.6667 | N34: =$L$34/12 -> 1666.6667 | O34: =$L$34/12 -> 1666.6667 | P34: =$L$34/12 -> 1666.6667 | Q34: =$L$34/12 -> 1666.6667 | R34: =$L$34/12 -> 1666.6667 | S34: =$L$34/12 -> 1666.6667 | T34: =$L$34/12 -> 1666.6667 | ... X34: =$L$34/12 -> 1666.6667
A35: Operating & Other Expenses | C35: Office Expenses | F35: 10000 | G35: 20000 | H35: 3000 | I35: 10000 | J35: 5000 | K35: 15000 | L35: 20000 | M35: =$L35/12 -> 1666.6667 | N35: =$L35/12 -> 1666.6667 | O35: =$L35/12 -> 1666.6667 | P35: =$L35/12 -> 1666.6667 | Q35: =$L35/12 -> 1666.6667 | R35: =$L35/12 -> 1666.6667 | S35: =$L35/12 -> 1666.6667 | T35: =$L35/12 -> 1666.6667 | ... X35: =$L35/12 -> 1666.6667
A36: Operating & Other Expenses | C36: Repairs | F36: 4000 | G36: 20000 | H36: 1000 | I36: 10000 | J36: 1000 | K36: 11000 | L36: 20000 | M36: =$L36/12 -> 1666.6667 | N36: =$L36/12 -> 1666.6667 | O36: =$L36/12 -> 1666.6667 | P36: =$L36/12 -> 1666.6667 | Q36: =$L36/12 -> 1666.6667 | R36: =$L36/12 -> 1666.6667 | S36: =$L36/12 -> 1666.6667 | T36: =$L36/12 -> 1666.6667 | ... X36: =$L36/12 -> 1666.6667
A37: Operating & Other Expenses | C37: Electricity | F37: 7000 | G37: 20000 | H37: 1000 | I37: 10000 | J37: 1000 | K37: 11000 | L37: 20000 | M37: =$L37/12 -> 1666.6667 | N37: =$L37/12 -> 1666.6667 | O37: =$L37/12 -> 1666.6667 | P37: =$L37/12 -> 1666.6667 | Q37: =$L37/12 -> 1666.6667 | R37: =$L37/12 -> 1666.6667 | S37: =$L37/12 -> 1666.6667 | T37: =$L37/12 -> 1666.6667 | ... X37: =$L37/12 -> 1666.6667
A38: Personnel cost | C38: Bonus Provision | F38: 0 | G38: 0 | H38: 0 | I38: 10000 | J38: 6000 | K38: 16000 | L38: 20000 | M38: =$L38/12 -> 1666.6667 | N38: =$L38/12 -> 1666.6667 | O38: =$L38/12 -> 1666.6667 | P38: =$L38/12 -> 1666.6667 | Q38: =$L38/12 -> 1666.6667 | R38: =$L38/12 -> 1666.6667 | S38: =$L38/12 -> 1666.6667 | T38: =$L38/12 -> 1666.6667 | ... X38: =$L38/12 -> 1666.6667
A39: Personnel cost | C39: Bonus Provision | K39: 0 | L39: 10000 | M39: =$L39/12 -> 833.33333 | N39: =$L39/12 -> 833.33333 | O39: =$L39/12 -> 833.33333 | P39: =$L39/12 -> 833.33333 | Q39: =$L39/12 -> 833.33333 | R39: =$L39/12 -> 833.33333 | S39: =$L39/12 -> 833.33333 | T39: =$L39/12 -> 833.33333 | ... X39: =$L39/12 -> 833.33333
A40: Personnel cost | C40: Payroll Insurance | F40: 3000 | G40: 10000 | H40: 9000 | I40: 7000 | J40: 5000 | K40: 12000 | L40: 10000 | M40: =$L40/12 -> 833.33333 | N40: =$L40/12 -> 833.33333 | O40: =$L40/12 -> 833.33333 | P40: =$L40/12 -> 833.33333 | Q40: =$L40/12 -> 833.33333 | R40: =$L40/12 -> 833.33333 | S40: =$L40/12 -> 833.33333 | T40: =$L40/12 -> 833.33333 | ... X40: =$L40/12 -> 833.33333
A41: Personnel cost | C41: Payroll Insurance | K41: 0 | L41: 10000 | M41: =$L41/12 -> 833.33333 | N41: =$L41/12 -> 833.33333 | O41: =$L41/12 -> 833.33333 | P41: =$L41/12 -> 833.33333 | Q41: =$L41/12 -> 833.33333 | R41: =$L41/12 -> 833.33333 | S41: =$L41/12 -> 833.33333 | T41: =$L41/12 -> 833.33333 | ... X41: =$L41/12 -> 833.33333
A42: Personnel cost | C42: Bonus - Staff | F42: 8000 | G42: 10000 | H42: 8000 | I42: 9000 | J42: 0 | K42: 9000 | L42: 10000 | M42: =$L42/12 -> 833.33333 | N42: =$L42/12 -> 833.33333 | O42: =$L42/12 -> 833.33333 | P42: =$L42/12 -> 833.33333 | Q42: =$L42/12 -> 833.33333 | R42: =$L42/12 -> 833.33333 | S42: =$L42/12 -> 833.33333 | T42: =$L42/12 -> 833.33333 | ... X42: =$L42/12 -> 833.33333
A43: Personnel cost | C43: Bonus - Staff | K43: 0 | L43: 10000 | M43: =$L43/12 -> 833.33333 | N43: =$L43/12 -> 833.33333 | O43: =$L43/12 -> 833.33333 | P43: =$L43/12 -> 833.33333 | Q43: =$L43/12 -> 833.33333 | R43: =$L43/12 -> 833.33333 | S43: =$L43/12 -> 833.33333 | T43: =$L43/12 -> 833.33333 | ... X43: =$L43/12 -> 833.33333
A44: Personnel cost | C44: Salaries - Staff | F44: 150000 | G44: 130000 | H44: 120000 | I44: 220000 | J44: 90000 | K44: 310000 | L44: 300000 | M44: =$L44/12 -> 25000 | N44: =$L44/12 -> 25000 | O44: =$L44/12 -> 25000 | P44: =$L44/12 -> 25000 | Q44: =$L44/12 -> 25000 | R44: =$L44/12 -> 25000 | S44: =$L44/12 -> 25000 | T44: =$L44/12 -> 25000 | ... X44: =$L44/12 -> 25000
A45: Personnel cost | C45: Salaries - Staff | K45: 0 | L45: 10000 | M45: =$L45/12 -> 833.33333 | N45: =$L45/12 -> 833.33333 | O45: =$L45/12 -> 833.33333 | P45: =$L45/12 -> 833.33333 | Q45: =$L45/12 -> 833.33333 | R45: =$L45/12 -> 833.33333 | S45: =$L45/12 -> 833.33333 | T45: =$L45/12 -> 833.33333 | ... X45: =$L45/12 -> 833.33333
A46: Personnel cost | C46: Wages | F46: 150000 | G46: 200000 | H46: 70000 | I46: 100000 | J46: 10000 | K46: 110000 | L46: 50000 | M46: =$L46/12 -> 4166.6667 | N46: =$L46/12 -> 4166.6667 | O46: =$L46/12 -> 4166.6667 | P46: =$L46/12 -> 4166.6667 | Q46: =$L46/12 -> 4166.6667 | R46: =$L46/12 -> 4166.6667 | S46: =$L46/12 -> 4166.6667 | T46: =$L46/12 -> 4166.6667 | ... X46: =$L46/12 -> 4166.6667
A47: Personnel cost | C47: Gratuity Provision | K47: 0 | L47: 5000 | M47: =$L47/12 -> 416.66667 | N47: =$L47/12 -> 416.66667 | O47: =$L47/12 -> 416.66667 | P47: =$L47/12 -> 416.66667 | Q47: =$L47/12 -> 416.66667 | R47: =$L47/12 -> 416.66667 | S47: =$L47/12 -> 416.66667 | T47: =$L47/12 -> 416.66667 | ... X47: =$L47/12 -> 416.66667
A48: Personnel cost | C48: Provident Fund | K48: 0 | L48: 5000 | M48: =$L48/12 -> 416.66667 | N48: =$L48/12 -> 416.66667 | O48: =$L48/12 -> 416.66667 | P48: =$L48/12 -> 416.66667 | Q48: =$L48/12 -> 416.66667 | R48: =$L48/12 -> 416.66667 | S48: =$L48/12 -> 416.66667 | T48: =$L48/12 -> 416.66667 | ... X48: =$L48/12 -> 416.66667
A49: Product Registration | C49: Registration Fees | F49: 10000 | G49: 30000 | H49: 6000 | I49: 10000 | J49: 10000 | K49: 20000 | L49: 5000 | M49: =$L49/12 -> 416.66667 | N49: =$L49/12 -> 416.66667 | O49: =$L49/12 -> 416.66667 | P49: =$L49/12 -> 416.66667 | Q49: =$L49/12 -> 416.66667 | R49: =$L49/12 -> 416.66667 | S49: =$L49/12 -> 416.66667 | T49: =$L49/12 -> 416.66667 | ... X49: =$L49/12 -> 416.66667
A50: Travel & Conveyance | C50: Conveyance | F50: 9000 | G50: 20000 | H50: 8000 | I50: 10000 | J50: 10000 | K50: 20000 | L50: 5000 | M50: =$L50/12 -> 416.66667 | N50: =$L50/12 -> 416.66667 | O50: =$L50/12 -> 416.66667 | P50: =$L50/12 -> 416.66667 | Q50: =$L50/12 -> 416.66667 | R50: =$L50/12 -> 416.66667 | S50: =$L50/12 -> 416.66667 | T50: =$L50/12 -> 416.66667 | ... X50: =$L50/12 -> 416.66667
A51: Travel & Conveyance | C51: Travel - International | F51: 1000 | G51: 10000 | H51: 1000 | I51: 10000 | J51: 10000 | K51: 20000 | L51: 5000 | M51: =$L51/12 -> 416.66667 | N51: =$L51/12 -> 416.66667 | O51: =$L51/12 -> 416.66667 | P51: =$L51/12 -> 416.66667 | Q51: =$L51/12 -> 416.66667 | R51: =$L51/12 -> 416.66667 | S51: =$L51/12 -> 416.66667 | T51: =$L51/12 -> 416.66667 | ... X51: =$L51/12 -> 416.66667
A52: Travel & Conveyance | C52: Travel - Domestic | F52: 3000 | G52: 8000 | H52: 4000 | I52: 10000 | J52: 10000 | K52: 20000 | L52: 5000 | M52: =$L52/12 -> 416.66667 | N52: =$L52/12 -> 416.66667 | O52: =$L52/12 -> 416.66667 | P52: =$L52/12 -> 416.66667 | Q52: =$L52/12 -> 416.66667 | R52: =$L52/12 -> 416.66667 | S52: =$L52/12 -> 416.66667 | T52: =$L52/12 -> 416.66667 | ... X52: =$L52/12 -> 416.66667
...

Sheet OH Summary
B1: ='Bud27 vs Proj26'!B1 -> Note: All figures are fictional and for illustration only.
B3: Overheads FY’27
B5: Particulars | C5: Projection | D5: Estimated | E5: Budget | G5: Variance | H5: Remarks
C6: FY'26 | D6: FY'25 | E6: FY'27 | F6: 9 Month Act | G6: %
B8: Overheads (excl.ECL/Bad Debts) | C8: =C10+C16 -> 932 | D8: =D10+D16 -> 906.66667 | E8: =E10+E16 -> 924 | F8: =F10+F16 -> 680 | G8: =(E8-C8)/C8 -> -0.008583691
B10: Fixed Component | C10: =SUM(C11:C14) -> 487 | D10: =SUM(D11:D14) -> 426.66667 | E10: =SUM(E11:E14) -> 473 | F10: =SUM(F11:F14) -> 320 | G10: =(E10-C10)/C10 -> -0.028747433
B11: Employee Benefits Expenses | C11: ='Bud27 vs Proj26'!E12/1000 -> 457 | D11: =F11/9*12 -> 400 | E11: ='Bud27 vs Proj26'!F12/1000 -> 440 | F11: 300 | G11: =(E11-C11)/C11 -> -0.037199125
B12: Rent | C12: 0 | D12: =F12/9*12 -> 0
B13: Rates and Taxes | C13: 0 | D13: =F13/9*12 -> 0
B14: Insurance | C14: ='Bud27 vs Proj26'!E10/1000 -> 30 | D14: =F14/9*12 -> 26.666667 | E14: ='Bud27 vs Proj26'!F10/1000 -> 33 | F14: 20 | G14: =(E14-C14)/C14 -> 0.1
B16: Variable Component | C16: =SUM(C17:C26) -> 445 | D16: =SUM(D17:D26) -> 480 | E16: =SUM(E17:E26) -> 451 | F16: =SUM(F17:F26) -> 360 | G16: =(E16-C16)/C16 -> 0.013483146
B17: Employee Benefits Exp - Contract | C17: 0 | D17: =F17/9*12 -> 0
B18: Legal & Professional Fees | C18: ='Bud27 vs Proj26'!E11/1000 -> 130 | D18: =F18/9*12 -> 120 | E18: ='Bud27 vs Proj26'!F11/1000 -> 140 | F18: 90 | G18: =(E18-C18)/C18 -> 0.076923077
B19: Travel & Conveyance | C19: ='Bud27 vs Proj26'!E15/1000 -> 60 | D19: =F19/9*12 -> 93.333333 | E19: ='Bud27 vs Proj26'!F15/1000 -> 15 | F19: 70 | G19: =(E19-C19)/C19 -> -0.75
B20: Advertisement & Sales Promotion | C20: ='Bud27 vs Proj26'!E7/1000 -> 63 | D20: =F20/9*12 -> 186.66667 | E20: ='Bud27 vs Proj26'!F7/1000 -> 61 | F20: 140 | G20: =(E20-C20)/C20 -> -0.031746032
B21: Warehousing Cost | C21: 0 | D21: =F21/9*12 -> 0 | E21: 0
B22: Communication Costs | C22: ='Bud27 vs Proj26'!E8/1000 -> 38 | D22: =F22/9*12 -> 13.333333 | E22: ='Bud27 vs Proj26'!F8/1000 -> 30 | F22: 10 | G22: =(E22-C22)/C22 -> -0.21052632
B23: Operating & Other Expenses | C23: ='Bud27 vs Proj26'!E13/1000 -> 134 | D23: =F23/9*12 -> 53.333333 | E23: ='Bud27 vs Proj26'!F13/1000 -> 200 | F23: 40 | G23: =(E23-C23)/C23 -> 0.49253731
B24: Product Registration | C24: ='Bud27 vs Proj26'!E14/1000 -> 20 | D24: =F24/9*12 -> 13.333333 | E24: ='Bud27 vs Proj26'!F14/1000 -> 5 | F24: 10 | G24: =(E24-C24)/C24 -> -0.75
B25: Repairs & Maintenance | C25: 0 | D25: =F25/9*12 -> 0 | E25: 0 | G25: =IFERROR((E25-C25)/C25,0) -> 0
B26: One Time costs | C26: 0 | D26: =F26/9*12 -> 0 | E26: =D26*1.5 -> 0 | G26: =IFERROR((E26-C26)/C26,0) -> 0
B28: ECL/ Bad debts | C28: 35 | D28: 50 | E28: 30 | F28: 10 | G28: =(E28-C28)/C28 -> -0.14285714
B30: Overheads (incl.ECL/Bad Debts) | C30: =C28+C8 -> 967 | D30: =D28+D8 -> 956.66667 | E30: =E28+E8 -> 954 | G30: =(E30-C30)/C30 -> -0.01344364
B32: Revenue | C32: 11000 | E32: 13000 | G32: =(E32-C32)/C32 -> 0.18181818
B33: % of Revenue | C33: =C30/C32 -> 0.087909091 | E33: =E30/E32 -> 0.073384615
B35: Overheads % to Contribution | C35: =C30/C36 -> 0.24175 | E35: =E30/E36 -> 0.1908
B36: Contri | C36: 4000 | E36: 5000

Sheet P&L
B2: ='OH Summary'!B1 -> Note: All figures are fictional and for illustration only.
B4: Particulars | C4: Budget | D4: Projection | E4: Budget | F4: Actual
C5: FY'27 | D5: FY'26 | E5: FY'26 | F5: FY'25
C6: FY | D6: FY | E6: FY | F6: FY
B7: Sales | C7: 13 | D7: 12 | E7: 11 | F7: 9
B8: Contribution | C8: 5 | D8: 4 | E8: 3.5 | F8: 3
B9: % of Revenue | C9: =C8/C7 -> 0.38461538 | D9: =D8/D7 -> 0.33333333 | E9: =E8/E7 -> 0.31818182 | F9: =F8/F7 -> 0.33333333
B10: Overhead | C10: ='Bud27 vs Proj26'!F16/1000000 -> 0.924 | D10: ='Bud27 vs Proj26'!E16/1000000 -> 0.932 | E10: ='Bud27 vs Proj26'!G16/1000000 -> 0.908 | F10: 0.79322948
B11: % of Revenue | C11: =C10/C7 -> 0.071076923 | D11: =D10/D7 -> 0.077666667 | E11: =E10/E7 -> 0.082545455 | F11: =F10/F7 -> 0.088136609
B12: EBITDA | C12: =C8-C10 -> 4.076 | D12: =D8-D10 -> 3.068 | E12: =E8-E10 -> 2.592 | F12: =F8-F10 -> 2.2067705
B13: % Revenue | C13: =C12/C7 -> 0.31353846 | D13: =D12/D7 -> 0.25566667 | E13: =E12/E7 -> 0.23563636 | F13: =F12/F7 -> 0.24519672
