Workbook

Sheet Dashboard
B1: =Assumptions!$D$5 -> Sample Aqua Ltd.
B2: Fish Farming and Hatchery Project: Dashboard
B3: ="Scenario: "&Assumptions!$D$11&" | BDT million unless stated" -> Scenario: Base case | BDT million unless stated
B5: PROFITABILITY | I5: INVESTMENT
B6: BDT million | C6: ='Income Statement'!E4 -> FY2026-27 | D6: ='Income Statement'!F4 -> FY2027-28 | E6: ='Income Statement'!G4 -> FY2028-29 | F6: ='Income Statement'!H4 -> FY2029-30 | G6: ='Income Statement'!I4 -> FY2030-31 | I6: Project cost and funding (BDT million)
B7: Revenue | C7: ='Income Statement'!E10/1000000 -> 12.08 | D7: ='Income Statement'!F10/1000000 -> 49.7175 | E7: ='Income Statement'!G10/1000000 -> 66.8115 | F7: ='Income Statement'!H10/1000000 -> 83.059594 | G7: ='Income Statement'!I10/1000000 -> 75.543713 | I7: Fixed assets (project cost) | J7: =Funding!D11/1000000 -> 45.792242
B8: Revenue growth | D8: ='Income Statement'!F11 -> 3.1156871 | E8: ='Income Statement'!G11 -> 0.3438226 | F8: ='Income Statement'!H11 -> 0.24319307 | G8: ='Income Statement'!I11 -> -0.090487805 | I8: Opening cash for Year 1 working capital | J8: =Funding!D12/1000000 -> 2.4199453
B9: Cost of goods sold (COGS) | C9: =-'Income Statement'!E18/1000000 -> 8.681334 | D9: =-'Income Statement'!F18/1000000 -> 22.562346 | E9: =-'Income Statement'!G18/1000000 -> 29.776102 | F9: =-'Income Statement'!H18/1000000 -> 30.865272 | G9: =-'Income Statement'!I18/1000000 -> 32.009687 | I9: Total funds needed | J9: =Funding!D13/1000000 -> 48.212188
B10: Gross profit | C10: ='Income Statement'!E19/1000000 -> 3.398666 | D10: ='Income Statement'!F19/1000000 -> 27.155154 | E10: ='Income Statement'!G19/1000000 -> 37.035398 | F10: ='Income Statement'!H19/1000000 -> 52.194322 | G10: ='Income Statement'!I19/1000000 -> 43.534027 | I10: Bank term loan | J10: =Funding!D16/1000000 -> 22.896121
B11: Gross margin | C11: ='Income Statement'!E20 -> 0.28134652 | D11: ='Income Statement'!F20 -> 0.54618906 | E11: ='Income Statement'!G20 -> 0.5543267 | F11: ='Income Statement'!H20 -> 0.62839607 | G11: ='Income Statement'!I20 -> 0.57627597 | I11: Owner equity | J11: =Funding!D17/1000000 -> 25.316066
B12: Operating expenses | C12: =-'Income Statement'!E27/1000000 -> 2.60655 | D12: =-'Income Statement'!F27/1000000 -> 5.043665 | E12: =-'Income Statement'!G27/1000000 -> 6.7408482 | F12: =-'Income Statement'!H27/1000000 -> 8.3542738 | G12: =-'Income Statement'!I27/1000000 -> 7.5923209 | I12: Owner share of total funds | J12: =Funding!D20 -> 0.52509682
B13: EBITDA | C13: ='Income Statement'!E28/1000000 -> 0.79211599 | D13: ='Income Statement'!F28/1000000 -> 22.111489 | E13: ='Income Statement'!G28/1000000 -> 30.29455 | F13: ='Income Statement'!H28/1000000 -> 43.840048 | G13: ='Income Statement'!I28/1000000 -> 35.941706
B14: EBITDA margin | C14: ='Income Statement'!E29 -> 0.065572516 | D14: ='Income Statement'!F29 -> 0.44474259 | E14: ='Income Statement'!G29 -> 0.45343317 | F14: ='Income Statement'!H29 -> 0.52781438 | G14: ='Income Statement'!I29 -> 0.47577362 | I14: Value of the project
B15: Depreciation and interest | C15: =-('Income Statement'!E30+'Income Statement'!E32)/1000000 -> 5.8464117 | D15: =-('Income Statement'!F30+'Income Statement'!F32)/1000000 -> 5.8464117 | E15: =-('Income Statement'!G30+'Income Statement'!G32)/1000000 -> 5.3595281 | F15: =-('Income Statement'!H30+'Income Statement'!H32)/1000000 -> 4.6726445 | G15: =-('Income Statement'!I30+'Income Statement'!I32)/1000000 -> 3.9857608 | I15: Discount rate = WACC | J15: ='Investment Analysis'!D16 -> 0.14633594
B16: Net profit after tax | C16: ='Income Statement'!E35/1000000 -> -5.0542957 | D16: ='Income Statement'!F35/1000000 -> 13.182113 | E16: ='Income Statement'!G35/1000000 -> 18.077891 | F16: ='Income Statement'!H35/1000000 -> 28.396368 | G16: ='Income Statement'!I35/1000000 -> 23.16806 | I16: NPV incl. recovery value (BDT million) | J16: ='Investment Analysis'!D44/1000000 -> 30.651569
B17: Net profit margin | C17: ='Income Statement'!E36 -> -0.41840196 | D17: ='Income Statement'!F36 -> 0.2651403 | E17: ='Income Statement'!G36 -> 0.27058053 | F17: ='Income Statement'!H36 -> 0.34187944 | G17: ='Income Statement'!I36 -> 0.30668416 | I17: IRR incl. recovery value | J17: ='Investment Analysis'!D45 -> 0.29333206
B18: Return on equity | C18: =Ratios!E12 -> -0.22248772 | D18: =Ratios!F12 -> 0.36903344 | E18: =Ratios!G12 -> 0.42088783 | F18: =Ratios!H12 -> 0.52285371 | G18: =Ratios!I12 -> 0.36440617 | I18: Payback period | J18: ='Investment Analysis'!D42 -> 3.6618855
B19: Profit before tax by unit, Year 4 | I19: Discounted payback period | J19: ='Investment Analysis'!D43 -> 4.7764457
B20: Hatchery | C20: ='Segment Analysis'!H38/1000000 -> 27.90562 | I20: Profitability index | J20: ='Investment Analysis'!D41 -> 1.0675609
B21: Farming | C21: ='Segment Analysis'!H41/1000000 -> 11.261784 | I21: NPV, 5 years only (BDT million) | J21: ='Investment Analysis'!D38/1000000 -> 3.093767
B22: COGS = feed, stock, hormone and factory overheads. Operating expenses = administrative, marketing, selling and distribution.
I23: Owner
I24: Total invested by the owner (BDT million) | J24: ='Owner Returns'!D29/1000000 -> 27.771485
B25: CASH FLOW STATEMENT | I25: Dividends in 5 years (BDT million) | J25: ='Owner Returns'!D30/1000000 -> 41.964048
B26: BDT million | C26: =C6 -> FY2026-27 | D26: =D6 -> FY2027-28 | E26: =E6 -> FY2028-29 | F26: =F6 -> FY2029-30 | G26: =G6 -> FY2030-31 | I26: Dividends as % of owner investment | J26: ='Owner Returns'!D31 -> 1.511048
B27: Cash flow from operations | C27: ='Cash Flow'!E13/1000000 -> -4.3753639 | D27: ='Cash Flow'!F13/1000000 -> 10.905687 | E27: ='Cash Flow'!G13/1000000 -> 18.785959 | F27: ='Cash Flow'!H13/1000000 -> 30.180743 | G27: ='Cash Flow'!I13/1000000 -> 26.896558 | I27: Owner IRR incl. book equity at end of Year 5 | J27: ='Owner Returns'!D35 -> 0.34750685
B28: Cash flow from investing | C28: ='Cash Flow'!E17/1000000 -> 0 | D28: ='Cash Flow'!F17/1000000 -> -5.003 | E28: ='Cash Flow'!G17/1000000 -> 0 | F28: ='Cash Flow'!H17/1000000 -> 0 | G28: ='Cash Flow'!I17/1000000 -> 0
B29: Cash flow from financing | C29: ='Cash Flow'!E24/1000000 -> 2.4554185 | D29: ='Cash Flow'!F24/1000000 -> -5.9026866 | E29: ='Cash Flow'!G24/1000000 -> -16.570765 | F29: ='Cash Flow'!H24/1000000 -> -22.761851 | G29: ='Cash Flow'!I24/1000000 -> -19.624866 | I29: Lender view
B30: Net change in cash | C30: ='Cash Flow'!E28/1000000 -> -1.9199453 | D30: ='Cash Flow'!F28/1000000 -> 0 | E30: ='Cash Flow'!G28/1000000 -> 2.215194 | F30: ='Cash Flow'!H28/1000000 -> 7.4188926 | G30: ='Cash Flow'!I28/1000000 -> 7.2716915 | I30: Minimum Debt Service Coverage Ratio (DSCR) | J30: ='Loan Analysis'!E35 -> 1.6116528
B31: Closing cash | C31: ='Cash Flow'!E30/1000000 -> 0.5 | D31: ='Cash Flow'!F30/1000000 -> 0.5 | E31: ='Cash Flow'!G30/1000000 -> 2.715194 | F31: ='Cash Flow'!H30/1000000 -> 10.134087 | G31: ='Cash Flow'!I30/1000000 -> 17.405778 | I31: Average Debt Service Coverage Ratio (DSCR) | J31: ='Loan Analysis'!E36 -> 3.2594516
I32: Minimum interest cover | J32: ='Loan Analysis'!E37 -> 6.9198811
B33: WORKING CAPITAL | I33: Collateral cover at drawdown | J33: ='Loan Analysis'!E39 -> 1.2997812
B34: BDT million | C34: =C6 -> FY2026-27 | D34: =D6 -> FY2027-28 | E34: =E6 -> FY2028-29 | F34: =F6 -> FY2029-30 | G34: =G6 -> FY2030-31 | I34: Lending benchmarks met | J34: ='Loan Analysis'!D43&" of "&'Loan Analysis'!E43 -> 8 of 8
B35: Net working capital | C35: ='Working Capital'!E15/1000000 -> 2.4199453 | D35: ='Working Capital'!F15/1000000 -> 7.7952486 | E35: ='Working Capital'!G15/1000000 -> 10.386058 | F35: ='Working Capital'!H15/1000000 -> 11.900559 | G35: ='Working Capital'!I15/1000000 -> 11.470939
B36: Net working capital as % of revenue | C36: ='Working Capital'!E17 -> 0.2003266 | D36: ='Working Capital'!F17 -> 0.15679084 | E36: ='Working Capital'!G17 -> 0.15545315 | F36: ='Working Capital'!H17 -> 0.14327736 | G36: ='Working Capital'!I17 -> 0.15184505 | I36: ='Investment Analysis'!D46 -> ACCEPT: NPV is positive and IRR is above the required return
B37: Cash conversion cycle (days) | C37: ='Working Capital'!E24 -> 90 | D37: ='Working Capital'!F24 -> 90 | E37: ='Working Capital'!G24 -> 90 | F37: ='Working Capital'!H24 -> 90 | G37: ='Working Capital'!I24 -> 90
I38: ='Loan Analysis'!B44 -> Result: the project meets all 8 lending benchmarks in the Base case.
B39: CASH FLOW GENERATION
B40: BDT million (outflows in brackets) | C40: =C6 -> FY2026-27 | D40: =D6 -> FY2027-28 | E40: =E6 -> FY2028-29 | F40: =F6 -> FY2029-30 | G40: =G6 -> FY2030-31
B41: EBITDA | C41: ='Cash Flow'!E37/1000000 -> 0.79211599 | D41: ='Cash Flow'!F37/1000000 -> 22.111489 | E41: ='Cash Flow'!G37/1000000 -> 30.29455 | F41: ='Cash Flow'!H37/1000000 -> 43.840048 | G41: ='Cash Flow'!I37/1000000 -> 35.941706
...

Sheet Assumptions
B1: Assumptions
B2: Inputs are the blue cells on this sheet and on the Farming, Hatchery, Operations and FA Schedule sheets.
B4: 1. General
B5: Company | C5: text | D5: Sample Aqua Ltd. | H5: Fish farming and hatchery project (one site: farming and hatchery)
B6: Currency | C6: text | D6: Bangladesh Taka (BDT)
B7: First financial year starts in | C7: year | D7: 2026 | H7: Year 1 = FY2026-27
B9: 2. Scenario selector
B10: Active scenario (1 Base, 2 Downside, 3 Upside) | C10: 1-3 | D10: 1 | H10: Change this one cell and the whole model re-runs
B11: Active scenario name | C11: text | D11: =CHOOSE(D10,"Base case","Downside case","Upside case") -> Base case
B13: Scenario factor | C13: Unit | D13: Base | E13: Downside | F13: Upside | G13: Active
B14: Selling price factor | C14: x | D14: 1 | E14: 0.9 | F14: 1.05 | G14: =CHOOSE($D$10,D14,E14,F14) -> 1
B15: Yield / volume factor | C15: x | D15: 1 | E15: 0.85 | F15: 1 | G15: =CHOOSE($D$10,D15,E15,F15) -> 1
B16: Feed price factor | C16: x | D16: 1 | E16: 1.1 | F16: 0.95 | G16: =CHOOSE($D$10,D16,E16,F16) -> 1
B17: Capital cost factor (land excluded) | C17: x | D17: 1 | E17: 1.1 | F17: 1 | G17: =CHOOSE($D$10,D17,E17,F17) -> 1
B18: Interest rate add-on | C18: pp | D18: 0 | E18: 0.02 | F18: 0 | G18: =CHOOSE($D$10,D18,E18,F18) -> 0
B20: 3. Yearly price and cost increases (Year 1 is the base year)
B21: Selling price increase per year: fish, fry and broodfish | C21: % a year | D21: 0.05
B22: Feed price increase per year | C22: % a year | D22: 0.05
B23: Salary increase per year | C23: % a year | D23: 0.05
B24: Two festival bonus equivalent to one months gross salary
B25: Administrative and other fixed cost increase per year | C25: % a year | D25: 0.1
B26: Fuel cost increase per year | C26: % a year | D26: 0.1
B27: Other operating cost increase per year | C27: % a year | D27: 0.05 | H27: Lime, entertainment, conveyance, parcelling materials, electricity, telephone and labour
B29: Selling price plan (BDT per unit) | C29: Unit | D29: Year 1 | E29: Increase a year | F29: Year 5
B30: Tilapia (grow-out fish) | C30: Tk per kg | D30: =Farming!C58 -> 110 | E30: =$D$21 -> 0.05 | F30: =D30*(1+E30)^4 -> 133.70569
B31: Carp (grow-out fish) | C31: Tk per kg | D31: =Farming!C59 -> 180 | E31: =$D$21 -> 0.05 | F31: =D31*(1+E31)^4 -> 218.79112
B32: Tilapia fry | C32: Tk per piece | D32: =Hatchery!C52 -> 0.8 | E32: =$D$21 -> 0.05 | F32: =D32*(1+E32)^4 -> 0.972405
B33: Carp fry | C33: Tk per kg | D33: =Hatchery!C53 -> 3500 | E33: =$D$21 -> 0.05 | F33: =D33*(1+E33)^4 -> 4254.2719
B34: Tilapia broodfish | C34: Tk per kg | D34: =Hatchery!C54 -> 150 | E34: =$D$21 -> 0.05 | F34: =D34*(1+E34)^4 -> 182.32594
B35: Carp broodfish | C35: Tk per kg | D35: =Hatchery!C55 -> 300 | E35: =$D$21 -> 0.05 | F35: =D35*(1+E35)^4 -> 364.65188
B36: Feed price (farming) | C36: Tk per kg | D36: =Farming!C50 -> 40 | E36: =$D$22 -> 0.05 | F36: =D36*(1+E36)^4 -> 48.62025
B38: 4. Tax, financing and dividends
B39: Corporate income tax rate | C39: % | D39: 0.275 | H39: Current rate used for this project: 27.5%. Tax losses are carried forward
B40: Interest rate on the term loan | C40: % | D40: 0.12 | H40: Interest charged on the opening loan balance
B41: Term loan as % of fixed assets cost | C41: % | D41: 0.5 | H41: Bank finances this share of the Year 0 fixed assets; the owner funds the rest plus the working capital reserve
B42: Loan tenor (including grace) | C42: years | D42: 5
B43: Grace period (interest only) | C43: years | D43: 1 | H43: No principal repaid in the grace years
B44: Minimum cash balance | C44: BDT | D44: 500000 | H44: If cash would fall below this, the owner injects the shortfall
B45: Dividend payout ratio | C45: % of profit | D45: 0.6 | H45: Paid only from profit after tax and only if the cash balance stays above the minimum
B47: 5. Discount rate (WACC) and bank benchmarks
...

Sheet Farming
D2: FISH PROJECT - Farming
D3: LAND AREA : 600 DECIMAL
I4: Fish Housing: 600 decimal x 250 pcs = 150,000 pcs
A5: Fish production and Feed Requirement Chart:
A6: FISH HOUSING: 150,000 PCS X 3 BATCH + 30% EXTRA = 585,000 PCS
A7: FINGERLING RELEASE DATE | B7: 2026 - 2027 | E7: 2027 - 2028 | H7: 2028 - 2029 | K7: 2029 - 2030
B8: Rearing Period | C8: Feed Requirement (KG) | D8: Fish Production (Kg) | E8: Rearing Period | F8: Feed Requirement (KG) | G8: Fish Production (Kg) | H8: Rearing Period | I8: Feed Requirement (KG) | J8: Fish Production (Kg) | K8: Rearing Period | L8: Feed Requirement (KG) | M8: Fish Production (Kg)
A9: 01.04.27 | B9: 01.04.27~15.07.27 | C9: =E29 -> 72500 | D9: =D29 -> 50000
A10: 01.07.27 | E10: 01.07.27~15.11.27 | F10: =E29 -> 72500 | G10: =D29 -> 50000
A11: 01.10.27 | E11: 01.10.27~31.03.28 | F11: =E29 -> 72500 | G11: =D29 -> 50000
A13: 01.04.28 | E13: 01.04.28~15.07.28 | F13: =E29 -> 72500 | G13: =D29 -> 50000
A14: 01.07.28 | H14: 01.07.28~15.11.28 | I14: =E29 -> 72500 | J14: =D29 -> 50000
A15: 01.10.28 | H15: 01.10.28~31.03.29 | I15: =E29 -> 72500 | J15: =D29 -> 50000
A17: 01.04.29 | H17: 01.04.29~15.07.29 | I17: =E29 -> 72500 | J17: =D29 -> 50000
A18: 01.07.29 | K18: 01.07.29~15.11.29 | L18: =E29 -> 72500 | M18: =D29 -> 50000
A19: 01.10.29 | K19: 01.10.29~31.03.30 | L19: =E29 -> 72500 | M19: =D29 -> 50000
A21: 01.04.30 | K21: 01.04.30~15.07.30 | L21: =E29 -> 72500 | M21: =D29 -> 50000
C22: =SUM(C9:C21) -> 72500 | D22: =SUM(D9:D21) -> 50000 | F22: =SUM(F9:F21) -> 217500 | G22: =SUM(G9:G21) -> 150000 | I22: =SUM(I9:I21) -> 217500 | J22: =SUM(J9:J21) -> 150000 | L22: =SUM(L9:L21) -> 217500 | M22: =SUM(M9:M21) -> 150000
A25: Feed Requirement in per cycle
A26: Fish Name | B26: Fingerling Qty (pcs) per cycle | C26: FCR | D26: Fish Production (kg) | E26: Feed Requirement | F26: ="Note: "&D26 -> Note: Fish Production (kg)
A27: Talapia | B27: 100000 | C27: 1.3 | D27: =B27/4 -> 25000 | E27: =C27*D27 -> 32500 | F27: If we provide all facilities, excepted production will be found.
A28: Carp | B28: 50000 | C28: 1.6 | D28: =B28/2 -> 25000 | E28: =C28*D28 -> 40000 | F28: If we provide all facilities, excepted production will be found.
B29: =SUM(B27:B28) -> 150000 | D29: =SUM(D27:D28) -> 50000 | E29: =SUM(E27:E28) -> 72500
A31: Feed Requirement circle wise
A32: Name of Feed | E32: Qty
A33: Nursery Feed | E33: =E29*5% -> 3625
A34: Starter Feed | E34: =E29*15% -> 10875
A35: Grower Feed | E35: =E29*80% -> 58000
A36: Total Feed per circle | E36: =SUM(E33:E35) -> 72500 | F36: 3 | G36: =E36*F36 -> 217500
A38: Feed Requirement Year Wise: | E38: Qty (kg)
A39: Name of Feed | E39: 2026 - 2027 | F39: 2027 - 2028 | G39: 2028 - 2029 | H39: 2029 - 2030
A40: Nursery Feed | E40: =C22*5% -> 3625 | F40: =F22*5% -> 10875 | G40: =I22*5% -> 10875 | H40: =L22*5% -> 10875
A41: Stater Feed | E41: =C22*15% -> 10875 | F41: =F22*15% -> 32625 | G41: =I22*15% -> 32625 | H41: =L22*15% -> 32625
A42: Grower Feed | E42: =C22*80% -> 58000 | F42: =F22*80% -> 174000 | G42: =I22*80% -> 174000 | H42: =L22*80% -> 174000
A43: Total Feed per circle | E43: =SUM(E40:E42) -> 72500 | F43: =SUM(F40:F42) -> 217500 | G43: =SUM(G40:G42) -> 217500 | H43: =SUM(H40:H42) -> 217500
A46: Variable cost estimation:
A47: Particulars | B47: 2026 - 2027 | E47: 2027 - 2028 | H47: 2028 - 2029 | K47: 2029 - 2030 | N47: 2030 - 2031
B48: Qty | C48: Unit cost | D48: Amt (Tk.) | E48: Qty | F48: Unit cost | G48: Amt (Tk.) | H48: Qty | I48: Unit cost | J48: Amt (Tk.) | K48: Qty | L48: Unit cost | M48: Amt (Tk.) | N48: Qty | O48: Unit cost | P48: Amt (Tk.)
A49: Fry / Fingerling | B49: =B29+(B29*$D$52) -> 195000 | C49: =D49/B49 -> 4 | D49: =B53*($B$27*$B$52+$B$28*$C$52)*(1+$D$52) -> 780000 | E49: =(B29*3)+(B29*3)*$D$52 -> 585000 | F49: =G49/E49 -> 2 | G49: =E53*($B$27*$B$52+$B$28*$C$52)*(1+$D$52) -> 1170000 | H49: =E49 -> 585000 | I49: =J49/H49 -> 2 | J49: =H53*($B$27*$B$52+$B$28*$C$52)*(1+$D$52) -> 1170000 | K49: =H49 -> 585000 | L49: =M49/K49 -> 2 | M49: =K53*($B$27*$B$52+$B$28*$C$52)*(1+$D$52) -> 1170000 | N49: =K49 -> 585000 | O49: =P49/N49 -> 2 | P49: =N53*($B$27*$B$52+$B$28*$C$52)*(1+$D$52) -> 1170000
A50: Feed | B50: =E43 -> 72500 | C50: 40 | D50: =B50*C50 -> 2900000 | E50: =F43 -> 217500 | F50: =C50*(1+Assumptions!$D$22) -> 42 | G50: =E50*F50 -> 9135000 | H50: =G43 -> 217500 | I50: =F50*(1+Assumptions!$D$22) -> 44.1 | J50: =H50*I50 -> 9591750 | K50: =H43 -> 217500 | L50: =I50*(1+Assumptions!$D$22) -> 46.305 | M50: =K50*L50 -> 10071338 | N50: =K50 -> 217500 | O50: =L50*(1+Assumptions!$D$22) -> 48.62025 | P50: =N50*O50 -> 10574904
...

Sheet Hatchery
D2: FISH PROJECT - Hatchery
D3: Hatchery Shed: 2 Shed
A4: Tilapia Fry
A5: EGG COLLECTION DATE | B5: 2026 - 2027 | D5: 2027 - 2028 | F5: 2028 - 2029 | H5: 2029 - 2030
B6: Rearing Period | C6: Fish Fry Production (Pc) | D6: Rearing Period | E6: Fish Fry Production (Pc) | F6: Rearing Period | G6: Fish Fry Production (Pc) | H6: Rearing Period | I6: Fish Fry Production (Pc)
D7: 01.07.27~31.07.27 | E7: 4000000 | F7: 01.07.28~31.07.28 | G7: =E7*1.5 -> 6000000 | H7: 01.07.29~31.07.29 | I7: =E7*2 -> 8000000
D8: 01.08.27~31.08.27 | E8: 4000000 | F8: 01.08.28~31.08.28 | G8: =E8*1.5 -> 6000000 | H8: 01.08.29~31.08.29 | I8: =E8*2 -> 8000000
D9: 01.09.27~30.09.27 | E9: 2000000 | F9: 01.09.28~30.09.28 | G9: =E9*1.5 -> 3000000 | H9: 01.09.29~30.09.29 | I9: =E9*2 -> 4000000
A10: 01.04.27 | B10: 01.04.27~30.04.27 | C10: 2000000 | D10: 01.04.28~30.04.28 | E10: =C10*1.5 -> 3000000 | F10: 01.04.29~30.04.29 | G10: =C10*2 -> 4000000 | H10: 01.04.30~30.04.30 | I10: =G10 -> 4000000
A11: 01.05.27 | B11: 01.05.27~31.05.27 | C11: 4000000 | D11: 01.05.28~31.05.28 | E11: =C11*1.5 -> 6000000 | F11: 01.05.29~31.05.29 | G11: =C11*2 -> 8000000 | H11: 01.05.30~31.05.30 | I11: =G11 -> 8000000
A12: 01.06.27 | B12: 01.06.27~30.06.27 | C12: 4000000 | D12: 01.06.28~30.06.28 | E12: =C12*1.5 -> 6000000 | F12: 01.06.29~30.06.29 | G12: =C12*2 -> 8000000 | H12: 01.06.30~30.06.30 | I12: =G12 -> 8000000
A13: Total | C13: =SUM(C7:C12) -> 10000000 | E13: =SUM(E7:E12) -> 25000000 | G13: =SUM(G7:G12) -> 35000000 | I13: =SUM(I7:I12) -> 40000000
A16: Carp Fry
A17: EGG COLLECTION DATE | B17: Year 2027 | D17: Year 2028 | F17: Year 2029
B18: Rearing Period | C18: Fish Fry Production (Kg) | D18: Rearing Period | E18: Fish Fry Production (Pc) | F18: Rearing Period | G18: Fish Fry Production (Pc)
A19: 01.03.27 | B19: 01.03.27~31.12.27 | C19: 1000 | E19: =C19*2.5 -> 2500 | G19: =E19*1.6 -> 4000
A21: Total | C21: =SUM(C19:C20) -> 1000 | E21: =SUM(E19:E20) -> 2500 | G21: =SUM(G19:G20) -> 4000
A25: Feed Requirement for Tilapia
A26: Fish Name | B26: Qty (pcs) | C26: FCR | D26: Fry Production (kg) | E26: Feed Requirement | F26: Rate | G26: Amt (Tk.) | H26: ="Note: "&D26 -> Note: Fry Production (kg)
A27: Tilapia - Fry | B27: 20000000 | C27: 1 | D27: =B27/3333 -> 6000.6001 | E27: =C27*D27 -> 6000.6001 | F27: 70 | G27: =E27*F27 -> 420042 | H27: If we provide all facilities, excepted production will be found.
A28: Tilapia - Broodfish | B28: 60000 | C28: 1.3 | D28: =B28/4 -> 15000 | E28: =B28*0.25*C28 -> 19500 | F28: 40 | G28: =E28*F28 -> 780000 | H28: This fish will be sold after 3rd year on the year of 2030
A29: Carp - Broodfish | B29: 5000 | C29: 1.6 | D29: =B29*2 -> 10000 | E29: =C29*D29 -> 16000 | F29: 40 | G29: =E29*F29 -> 640000
A30: Carp - Fry | B30: 1000 | D30: =B30 -> 1000 | E30: 0 | F30: - | G30: 0 | H30: No feed is required for Carp fry
E32: =SUM(E27:E31) -> 41500.6 | G32: =SUM(G27:G31) -> 1840042
A34: Note: Cycle 5 days, 1st day brood collection, 2nd day egg collection, 3rd day egg fertilization, 4th and 5th fry rearing
A37: Variable cost estimation:
A38: Particulars | B38: 2026 - 2027 | E38: 2027 - 2028 | H38: 2028 - 2029 | K38: 2029 - 2030 | N38: 2030 - 2031
B39: Qty | C39: Unit cost | D39: Amt (Tk.) | E39: Qty | F39: Unit cost | G39: Amt (Tk.) | H39: Qty | I39: Unit cost | J39: Amt (Tk.) | K39: Qty | L39: Unit cost | M39: Amt (Tk.) | N39: Qty | O39: Unit cost | P39: Amt (Tk.)
A40: Brood Tilapia | B40: =B28 -> 60000 | C40: 2 | D40: =B40*C40 -> 120000 | E40: =B40*2.5 -> 150000 | F40: 2 | G40: =E40*F40 -> 300000 | H40: =E40*1.6 -> 240000 | I40: =F40 -> 2 | J40: =H40*I40 -> 480000 | K40: =H40 -> 240000 | L40: =I40 -> 2 | M40: =K40*L40 -> 480000 | N40: =K40 -> 240000 | O40: =L40 -> 2 | P40: =N40*O40 -> 480000
A41: Brood Carp | B41: =B29 -> 5000 | C41: 5 | D41: =B41*C41 -> 25000 | E41: =B41*2.5 -> 12500 | F41: 5 | G41: =E41*F41 -> 62500 | H41: =E41*1.6 -> 20000 | I41: =F41 -> 5 | J41: =H41*I41 -> 100000 | K41: =H41 -> 20000 | L41: =I41 -> 5 | M41: =K41*L41 -> 100000 | N41: =K41 -> 20000 | O41: =L41 -> 5 | P41: =N41*O41 -> 100000
A42: Total Brood | D42: =SUBTOTAL(9,D40:D41) -> 145000 | G42: =SUBTOTAL(9,G40:G41) -> 362500 | J42: =SUBTOTAL(9,J40:J41) -> 580000 | M42: =SUBTOTAL(9,M40:M41) -> 580000 | P42: =SUBTOTAL(9,P40:P41) -> 580000
A43: Feed | B43: =E32 -> 41500.6 | C43: =D43/B43 -> 44.33772 | D43: =G32 -> 1840042 | E43: =B43*2.5 -> 103751.5 | F43: =C43*(1+Assumptions!$D$22) -> 46.554606 | G43: =E43*F43 -> 4830110.3 | H43: =E43*1.6 -> 166002.4 | I43: =F43*(1+Assumptions!$D$22) -> 48.882337 | J43: =H43*I43 -> 8114585.2 | K43: =H43 -> 166002.4 | L43: =I43*(1+Assumptions!$D$22) -> 51.326454 | M43: =K43*L43 -> 8520314.5 | N43: =K43 -> 166002.4 | O43: =L43*(1+Assumptions!$D$22) -> 53.892776 | P43: =N43*O43 -> 8946330.2
A44: Feed for fry (kg) | B44: =E27 -> 6000.6001 | C44: 70 | D44: =B44*C44 -> 420042 | E44: =B44*2.5 -> 15001.5 | F44: =C44*(1+Assumptions!$D$22) -> 73.5 | G44: =E44*F44 -> 1102610.3 | H44: =E44*1.6 -> 24002.4 | I44: =F44*(1+Assumptions!$D$22) -> 77.175 | J44: =H44*I44 -> 1852385.2 | K44: =H44 -> 24002.4 | L44: =I44*(1+Assumptions!$D$22) -> 81.03375 | M44: =K44*L44 -> 1945004.5 | N44: =K44 -> 24002.4 | O44: =L44*(1+Assumptions!$D$22) -> 85.085437 | P44: =N44*O44 -> 2042254.7
A45: Total Feed | D45: =SUBTOTAL(9,D43:D44) -> 2260084 | G45: =SUBTOTAL(9,G43:G44) -> 5932720.5 | J45: =SUBTOTAL(9,J43:J44) -> 9966970.5 | M45: =SUBTOTAL(9,M43:M44) -> 10465319 | P45: =SUBTOTAL(9,P43:P44) -> 10988585
A46: Hormone 10ml recipient of oval prim | B46: 40 | C46: 40000 | D46: =B46*C46 -> 1600000 | E46: =B46*2.5 -> 100 | F46: =C46 -> 40000 | G46: =E46*F46 -> 4000000 | H46: =E46*1.6 -> 160 | I46: =F46 -> 40000 | J46: =H46*I46 -> 6400000 | K46: =H46 -> 160 | L46: =I46 -> 40000 | M46: =K46*L46 -> 6400000 | N46: =K46 -> 160 | O46: =L46 -> 40000 | P46: =N46*O46 -> 6400000
A47: Total | D47: =SUBTOTAL(9,D40:D46) -> 4005084 | G47: =SUBTOTAL(9,G40:G46) -> 10295221 | J47: =SUBTOTAL(9,J40:J46) -> 16946970 | M47: =SUBTOTAL(9,M40:M46) -> 17445319 | P47: =SUBTOTAL(9,P40:P46) -> 17968585
A49: Revenue: selling rate rises every year (increase set on the Assumptions sheet)
A50: Particulars | B50: 2026 - 2027 | E50: 2027 - 2028 | H50: 2028 - 2029 | K50: 2029 - 2030 | N50: 2030 - 2031
B51: Qty | C51: Selling rate (Tk) | D51: Amt (Tk.) | E51: Qty | F51: Selling rate (Tk) | G51: Amt (Tk.) | H51: Qty | I51: Selling rate (Tk) | J51: Amt (Tk.) | K51: Qty | L51: Selling rate (Tk) | M51: Amt (Tk.) | N51: Qty | O51: Selling rate (Tk) | P51: Amt (Tk.)
A52: Tilapia fry (pcs) | B52: =I72 -> 10000000 | C52: 0.8 | D52: =B52*C52 -> 8000000 | E52: =V72 -> 25000000 | F52: =C52*(1+Assumptions!$D$21) -> 0.84 | G52: =E52*F52 -> 21000000 | H52: =AI72 -> 35000000 | I52: =F52*(1+Assumptions!$D$21) -> 0.882 | J52: =H52*I52 -> 30870000 | K52: =AV72 -> 40000000 | L52: =I52*(1+Assumptions!$D$21) -> 0.9261 | M52: =K52*L52 -> 37044000 | N52: =K52 -> 40000000 | O52: =L52*(1+Assumptions!$D$21) -> 0.972405 | P52: =N52*O52 -> 38896200
...

Sheet FA Schedule
B1: Capital Expenditure and Depreciation
B2: Straight-line depreciation starts in the year after purchase
B3: ="Scenario: "&Assumptions!$D$11&" | BDT'000 unless stated" -> Scenario: Base case | BDT'000 unless stated
B4: Financial year | C4: Unit | D4: Opening | E4: ="FY"&(Assumptions!$D$7+E5-1)&"-"&TEXT(MOD(Assumptions!$D$7+E5,100),"00") -> FY2026-27 | F4: ="FY"&(Assumptions!$D$7+F5-1)&"-"&TEXT(MOD(Assumptions!$D$7+F5,100),"00") -> FY2027-28 | G4: ="FY"&(Assumptions!$D$7+G5-1)&"-"&TEXT(MOD(Assumptions!$D$7+G5,100),"00") -> FY2028-29 | H4: ="FY"&(Assumptions!$D$7+H5-1)&"-"&TEXT(MOD(Assumptions!$D$7+H5,100),"00") -> FY2029-30 | I4: ="FY"&(Assumptions!$D$7+I5-1)&"-"&TEXT(MOD(Assumptions!$D$7+I5,100),"00") -> FY2030-31
D5: 0 | E5: 1 | F5: 2 | G5: 3 | H5: 4 | I5: 5
B7: Capital expenditure
B8: Land | C8: BDT | D8: =$E$62 -> 17080078 | E8: 0 | F8: =Assumptions!$D$68*Assumptions!$D$69 -> 3003000 | G8: 0 | H8: 0 | I8: 0
B9: Ponds and earthworks | C9: BDT | D9: =$E$63*Assumptions!$G$17 -> 3835704.8 | E9: 0 | F9: 0 | G9: 0 | H9: 0 | I9: 0
B10: Buildings and civil works | C10: BDT | D10: =$E$64*Assumptions!$G$17 -> 18764147 | E10: 0 | F10: =Assumptions!$D$67*Assumptions!$G$17 -> 2000000 | G10: 0 | H10: 0 | I10: 0
B11: Overhead water tanks | C11: BDT | D11: =$E$67*Assumptions!$G$17 -> 1000000 | E11: 0 | F11: 0 | G11: 0 | H11: 0 | I11: 0
B12: Equipment (including 5% contingency) | C12: BDT | D12: =$E$82*Assumptions!$G$17 -> 1912312.5 | E12: 0 | F12: 0 | G12: 0 | H12: 0 | I12: 0
B13: Vehicles | C13: BDT | D13: =$E$66*Assumptions!$G$17 -> 3000000 | E13: 0 | F13: 0 | G13: 0 | H13: 0 | I13: 0
B14: Furniture and fixtures | C14: BDT | D14: =$E$65*Assumptions!$G$17 -> 200000 | E14: 0 | F14: 0 | G14: 0 | H14: 0 | I14: 0
B15: Total capital expenditure | C15: BDT | D15: =SUM(D8:D14) -> 45792242 | E15: =SUM(E8:E14) -> 0 | F15: =SUM(F8:F14) -> 5003000 | G15: =SUM(G8:G14) -> 0 | H15: =SUM(H8:H14) -> 0 | I15: =SUM(I8:I14) -> 0
B16: of which depreciable | C16: BDT | D16: =D15-D8-D9 -> 24876459 | E16: =E15-E8-E9 -> 0 | F16: =F15-F8-F9 -> 2000000 | G16: =G15-G8-G9 -> 0 | H16: =H15-H8-H9 -> 0 | I16: =I15-I8-I9 -> 0
B18: Depreciation (rate in column C, straight line on cost)
B19: Buildings and civil works | C19: =Assumptions!$D$77 -> 0.1 | E19: =MIN($C19*SUM($D10:D10),SUM($D10:D10)-SUM($D19:D19)) -> 1876414.7 | F19: =MIN($C19*SUM($D10:E10),SUM($D10:E10)-SUM($D19:E19)) -> 1876414.7 | G19: =MIN($C19*SUM($D10:F10),SUM($D10:F10)-SUM($D19:F19)) -> 2076414.7 | H19: =MIN($C19*SUM($D10:G10),SUM($D10:G10)-SUM($D19:G19)) -> 2076414.7 | I19: =MIN($C19*SUM($D10:H10),SUM($D10:H10)-SUM($D19:H19)) -> 2076414.7
B20: Overhead water tanks | C20: =Assumptions!$D$78 -> 0.2 | E20: =MIN($C20*SUM($D11:D11),SUM($D11:D11)-SUM($D20:D20)) -> 200000 | F20: =MIN($C20*SUM($D11:E11),SUM($D11:E11)-SUM($D20:E20)) -> 200000 | G20: =MIN($C20*SUM($D11:F11),SUM($D11:F11)-SUM($D20:F20)) -> 200000 | H20: =MIN($C20*SUM($D11:G11),SUM($D11:G11)-SUM($D20:G20)) -> 200000 | I20: =MIN($C20*SUM($D11:H11),SUM($D11:H11)-SUM($D20:H20)) -> 200000
B21: Equipment | C21: =Assumptions!$D$79 -> 0.2 | E21: =MIN($C21*SUM($D12:D12),SUM($D12:D12)-SUM($D21:D21)) -> 382462.5 | F21: =MIN($C21*SUM($D12:E12),SUM($D12:E12)-SUM($D21:E21)) -> 382462.5 | G21: =MIN($C21*SUM($D12:F12),SUM($D12:F12)-SUM($D21:F21)) -> 382462.5 | H21: =MIN($C21*SUM($D12:G12),SUM($D12:G12)-SUM($D21:G21)) -> 382462.5 | I21: =MIN($C21*SUM($D12:H12),SUM($D12:H12)-SUM($D21:H21)) -> 382462.5
B22: Vehicles | C22: =Assumptions!$D$80 -> 0.2 | E22: =MIN($C22*SUM($D13:D13),SUM($D13:D13)-SUM($D22:D22)) -> 600000 | F22: =MIN($C22*SUM($D13:E13),SUM($D13:E13)-SUM($D22:E22)) -> 600000 | G22: =MIN($C22*SUM($D13:F13),SUM($D13:F13)-SUM($D22:F22)) -> 600000 | H22: =MIN($C22*SUM($D13:G13),SUM($D13:G13)-SUM($D22:G22)) -> 600000 | I22: =MIN($C22*SUM($D13:H13),SUM($D13:H13)-SUM($D22:H22)) -> 600000
B23: Furniture and fixtures | C23: =Assumptions!$D$81 -> 0.2 | E23: =MIN($C23*SUM($D14:D14),SUM($D14:D14)-SUM($D23:D23)) -> 40000 | F23: =MIN($C23*SUM($D14:E14),SUM($D14:E14)-SUM($D23:E23)) -> 40000 | G23: =MIN($C23*SUM($D14:F14),SUM($D14:F14)-SUM($D23:F23)) -> 40000 | H23: =MIN($C23*SUM($D14:G14),SUM($D14:G14)-SUM($D23:G23)) -> 40000 | I23: =MIN($C23*SUM($D14:H14),SUM($D14:H14)-SUM($D23:H23)) -> 40000
B24: Total depreciation | C24: BDT | E24: =SUM(E19:E23) -> 3098877.2 | F24: =SUM(F19:F23) -> 3098877.2 | G24: =SUM(G19:G23) -> 3298877.2 | H24: =SUM(H19:H23) -> 3298877.2 | I24: =SUM(I19:I23) -> 3298877.2
B25: of which hatchery share | C25: BDT | E25: =E24*Assumptions!$D$59 -> 2169214 | F25: =F24*Assumptions!$D$59 -> 2169214 | G25: =G24*Assumptions!$D$59 -> 2309214 | H25: =H24*Assumptions!$D$59 -> 2309214 | I25: =I24*Assumptions!$D$59 -> 2309214
B27: Net book value
B28: Depreciable assets at cost, closing | C28: BDT | D28: =SUM($D10:D10)+SUM($D11:D11)+SUM($D12:D12)+SUM($D13:D13)+SUM($D14:D14) -> 24876459 | E28: =SUM($D10:E10)+SUM($D11:E11)+SUM($D12:E12)+SUM($D13:E13)+SUM($D14:E14) -> 24876459 | F28: =SUM($D10:F10)+SUM($D11:F11)+SUM($D12:F12)+SUM($D13:F13)+SUM($D14:F14) -> 26876459 | G28: =SUM($D10:G10)+SUM($D11:G11)+SUM($D12:G12)+SUM($D13:G13)+SUM($D14:G14) -> 26876459 | H28: =SUM($D10:H10)+SUM($D11:H11)+SUM($D12:H12)+SUM($D13:H13)+SUM($D14:H14) -> 26876459 | I28: =SUM($D10:I10)+SUM($D11:I11)+SUM($D12:I12)+SUM($D13:I13)+SUM($D14:I14) -> 26876459
B29: Accumulated depreciation, closing | C29: BDT | D29: =SUM($D24:D24) -> 0 | E29: =SUM($D24:E24) -> 3098877.2 | F29: =SUM($D24:F24) -> 6197754.4 | G29: =SUM($D24:G24) -> 9496631.6 | H29: =SUM($D24:H24) -> 12795509 | I29: =SUM($D24:I24) -> 16094386
B30: Net book value, depreciable assets | C30: BDT | D30: =D28-D29 -> 24876459 | E30: =E28-E29 -> 21777582 | F30: =F28-F29 -> 20678705 | G30: =G28-G29 -> 17379828 | H30: =H28-H29 -> 14080951 | I30: =I28-I29 -> 10782073
B31: Land and ponds at cost (not depreciated) | C31: BDT | D31: =SUM($D8:D8)+SUM($D9:D9) -> 20915783 | E31: =SUM($D8:E8)+SUM($D9:E9) -> 20915783 | F31: =SUM($D8:F8)+SUM($D9:F9) -> 23918783 | G31: =SUM($D8:G8)+SUM($D9:G9) -> 23918783 | H31: =SUM($D8:H8)+SUM($D9:H9) -> 23918783 | I31: =SUM($D8:I8)+SUM($D9:I9) -> 23918783
B32: Total fixed assets, net | C32: BDT | D32: =D30+D31 -> 45792242 | E32: =E30+E31 -> 42693365 | F32: =F30+F31 -> 44597488 | G32: =G30+G31 -> 41298611 | H32: =H30+H31 -> 37999733 | I32: =I30+I31 -> 34700856
B33: Fixed assets at cost, closing | C33: BDT | D33: =D28+D31 -> 45792242 | E33: =E28+E31 -> 45792242 | F33: =F28+F31 -> 50795242 | G33: =G28+G31 -> 50795242 | H33: =H28+H31 -> 50795242 | I33: =I28+I31 -> 50795242
B34: Security: land, ponds and buildings at cost | C34: BDT | D34: =SUM($D8:D8)+SUM($D9:D9)+SUM($D10:D10) -> 39679930 | E34: =SUM($D8:E8)+SUM($D9:E9)+SUM($D10:E10) -> 39679930 | F34: =SUM($D8:F8)+SUM($D9:F9)+SUM($D10:F10) -> 44682930 | G34: =SUM($D8:G8)+SUM($D9:G9)+SUM($D10:G10) -> 44682930 | H34: =SUM($D8:H8)+SUM($D9:H9)+SUM($D10:H10) -> 44682930 | I34: =SUM($D8:I8)+SUM($D9:I9)+SUM($D10:I10) -> 44682930
B58: List of assets (figures in Taka)
B60: Land and Building
B61: Particulars | C61: Qty | D61: Cost | E61: Amt (Tk.)
B62: Land | C62: 1589 | D62: =E62/C62 -> 10748.948 | E62: 17080078
B63: Ponds | C63: 17 | D63: =E63/C63 -> 225629.69 | E63: 3835704.8
B64: Building | E64: 18764147
B65: Furniture & Fixtures | E65: 200000
B66: Vehicle | E66: 3000000
B67: Overhead tank. | C67: 10 | D67: =E67/C67 -> 100000 | E67: 1000000
...

Sheet Operations
B1: Operations: Revenue and Operating Costs
B2: Revenue and direct costs are picked up from the Farming and Hatchery sheets; overheads come from the cost build-up at the bottom of this sheet.
B3: ="Scenario: "&Assumptions!$D$11&" | BDT '000 unless stated" -> Scenario: Base case | BDT '000 unless stated
B4: Financial year | C4: Unit | D4: Opening | E4: ="FY"&(Assumptions!$D$7+E5-1)&"-"&TEXT(MOD(Assumptions!$D$7+E5,100),"00") -> FY2026-27 | F4: ="FY"&(Assumptions!$D$7+F5-1)&"-"&TEXT(MOD(Assumptions!$D$7+F5,100),"00") -> FY2027-28 | G4: ="FY"&(Assumptions!$D$7+G5-1)&"-"&TEXT(MOD(Assumptions!$D$7+G5,100),"00") -> FY2028-29 | H4: ="FY"&(Assumptions!$D$7+H5-1)&"-"&TEXT(MOD(Assumptions!$D$7+H5,100),"00") -> FY2029-30 | I4: ="FY"&(Assumptions!$D$7+I5-1)&"-"&TEXT(MOD(Assumptions!$D$7+I5,100),"00") -> FY2030-31
D5: 0 | E5: 1 | F5: 2 | G5: 3 | H5: 4 | I5: 5
B7: A. Revenue (BDT thousand): picked up from the Hatchery and Farming sheets
B8: Hatchery: tilapia fry | C8: BDT | E8: =Hatchery!D52*Assumptions!$G$14*Assumptions!$G$15 -> 8000000 | F8: =Hatchery!G52*Assumptions!$G$14*Assumptions!$G$15 -> 21000000 | G8: =Hatchery!J52*Assumptions!$G$14*Assumptions!$G$15 -> 30870000 | H8: =Hatchery!M52*Assumptions!$G$14*Assumptions!$G$15 -> 37044000 | I8: =Hatchery!P52*Assumptions!$G$14*Assumptions!$G$15 -> 38896200
B9: Hatchery: carp fry | C9: BDT | E9: =Hatchery!D53*Assumptions!$G$14*Assumptions!$G$15 -> 1400000 | F9: =Hatchery!G53*Assumptions!$G$14*Assumptions!$G$15 -> 5880000 | G9: =Hatchery!J53*Assumptions!$G$14*Assumptions!$G$15 -> 11962125 | H9: =Hatchery!M53*Assumptions!$G$14*Assumptions!$G$15 -> 9724050 | I9: =Hatchery!P53*Assumptions!$G$14*Assumptions!$G$15 -> 10210252
B10: Hatchery: tilapia broodfish | C10: BDT | E10: =Hatchery!D54*Assumptions!$G$14*Assumptions!$G$15 -> 0 | F10: =Hatchery!G54*Assumptions!$G$14*Assumptions!$G$15 -> 0 | G10: =Hatchery!J54*Assumptions!$G$14*Assumptions!$G$15 -> 0 | H10: =Hatchery!M54*Assumptions!$G$14*Assumptions!$G$15 -> 4167450 | I10: =Hatchery!P54*Assumptions!$G$14*Assumptions!$G$15 -> 0
B11: Hatchery: carp broodfish | C11: BDT | E11: =Hatchery!D55*Assumptions!$G$14*Assumptions!$G$15 -> 0 | F11: =Hatchery!G55*Assumptions!$G$14*Assumptions!$G$15 -> 0 | G11: =Hatchery!J55*Assumptions!$G$14*Assumptions!$G$15 -> 0 | H11: =Hatchery!M55*Assumptions!$G$14*Assumptions!$G$15 -> 6945750 | I11: =Hatchery!P55*Assumptions!$G$14*Assumptions!$G$15 -> 0
B12: Hatchery revenue | C12: BDT | E12: =E8+E9+E10+E11 -> 9400000 | F12: =F8+F9+F10+F11 -> 26880000 | G12: =G8+G9+G10+G11 -> 42832125 | H12: =H8+H9+H10+H11 -> 57881250 | I12: =I8+I9+I10+I11 -> 49106453
B13: Farming: tilapia | C13: BDT | E13: =Farming!D58*Assumptions!$G$14*Assumptions!$G$15 -> 880000 | F13: =Farming!G58*Assumptions!$G$14*Assumptions!$G$15 -> 8662500 | G13: =Farming!J58*Assumptions!$G$14*Assumptions!$G$15 -> 9095625 | H13: =Farming!M58*Assumptions!$G$14*Assumptions!$G$15 -> 9550406.2 | I13: =Farming!P58*Assumptions!$G$14*Assumptions!$G$15 -> 10027927
B14: Farming: carp | C14: BDT | E14: =Farming!D59*Assumptions!$G$14*Assumptions!$G$15 -> 1800000 | F14: =Farming!G59*Assumptions!$G$14*Assumptions!$G$15 -> 14175000 | G14: =Farming!J59*Assumptions!$G$14*Assumptions!$G$15 -> 14883750 | H14: =Farming!M59*Assumptions!$G$14*Assumptions!$G$15 -> 15627938 | I14: =Farming!P59*Assumptions!$G$14*Assumptions!$G$15 -> 16409334
B15: Farming revenue | C15: BDT | E15: =E13+E14 -> 2680000 | F15: =F13+F14 -> 22837500 | G15: =G13+G14 -> 23979375 | H15: =H13+H14 -> 25178344 | I15: =I13+I14 -> 26437261
B16: Total revenue | C16: BDT | E16: =E12+E15 -> 12080000 | F16: =F12+F15 -> 49717500 | G16: =G12+G15 -> 66811500 | H16: =H12+H15 -> 83059594 | I16: =I12+I15 -> 75543713
B18: B. Selling rates used (BDT per unit): they rise every year by the price increase on the Assumptions sheet
B19: Tilapia (per kg) | C19: BDT | E19: =Farming!C58*Assumptions!$G$14 -> 110 | F19: =Farming!F58*Assumptions!$G$14 -> 115.5 | G19: =Farming!I58*Assumptions!$G$14 -> 121.275 | H19: =Farming!L58*Assumptions!$G$14 -> 127.33875 | I19: =Farming!O58*Assumptions!$G$14 -> 133.70569
B20: Carp (per kg) | C20: BDT | E20: =Farming!C59*Assumptions!$G$14 -> 180 | F20: =Farming!F59*Assumptions!$G$14 -> 189 | G20: =Farming!I59*Assumptions!$G$14 -> 198.45 | H20: =Farming!L59*Assumptions!$G$14 -> 208.3725 | I20: =Farming!O59*Assumptions!$G$14 -> 218.79113
B21: Tilapia fry (per piece) | C21: BDT | E21: =Hatchery!C52*Assumptions!$G$14 -> 0.8 | F21: =Hatchery!F52*Assumptions!$G$14 -> 0.84 | G21: =Hatchery!I52*Assumptions!$G$14 -> 0.882 | H21: =Hatchery!L52*Assumptions!$G$14 -> 0.9261 | I21: =Hatchery!O52*Assumptions!$G$14 -> 0.972405
B22: Carp fry (per kg) | C22: BDT | E22: =Hatchery!C53*Assumptions!$G$14 -> 3500 | F22: =Hatchery!F53*Assumptions!$G$14 -> 3675 | G22: =Hatchery!I53*Assumptions!$G$14 -> 3858.75 | H22: =Hatchery!L53*Assumptions!$G$14 -> 4051.6875 | I22: =Hatchery!O53*Assumptions!$G$14 -> 4254.2719
B23: Tilapia broodfish (per kg, sold in Year 4) | C23: BDT | E23: =Hatchery!C54*Assumptions!$G$14 -> 150 | F23: =Hatchery!F54*Assumptions!$G$14 -> 157.5 | G23: =Hatchery!I54*Assumptions!$G$14 -> 165.375 | H23: =Hatchery!L54*Assumptions!$G$14 -> 173.64375 | I23: =Hatchery!O54*Assumptions!$G$14 -> 182.32594
B24: Carp broodfish (per kg, sold in Year 4) | C24: BDT | E24: =Hatchery!C55*Assumptions!$G$14 -> 300 | F24: =Hatchery!F55*Assumptions!$G$14 -> 315 | G24: =Hatchery!I55*Assumptions!$G$14 -> 330.75 | H24: =Hatchery!L55*Assumptions!$G$14 -> 347.2875 | I24: =Hatchery!O55*Assumptions!$G$14 -> 364.65188
B25: Yearly increase in the selling rate | C25: % | F25: =IFERROR(F19/E19-1,0) -> 0.05 | G25: =IFERROR(G19/F19-1,0) -> 0.05 | H25: =IFERROR(H19/G19-1,0) -> 0.05 | I25: =IFERROR(I19/H19-1,0) -> 0.05
B27: C. Variable costs (BDT thousand): they move with production and sales
B28: Feed: hatchery | C28: BDT | E28: =Hatchery!D45*Assumptions!$G$15*Assumptions!$G$16 -> 2260084 | F28: =Hatchery!G45*Assumptions!$G$15*Assumptions!$G$16 -> 5932720.5 | G28: =Hatchery!J45*Assumptions!$G$15*Assumptions!$G$16 -> 9966970.5 | H28: =Hatchery!M45*Assumptions!$G$15*Assumptions!$G$16 -> 10465319 | I28: =Hatchery!P45*Assumptions!$G$15*Assumptions!$G$16 -> 10988585
B29: Feed: farming | C29: BDT | E29: =Farming!D50*Assumptions!$G$15*Assumptions!$G$16 -> 2900000 | F29: =Farming!G50*Assumptions!$G$15*Assumptions!$G$16 -> 9135000 | G29: =Farming!J50*Assumptions!$G$15*Assumptions!$G$16 -> 9591750 | H29: =Farming!M50*Assumptions!$G$15*Assumptions!$G$16 -> 10071338 | I29: =Farming!P50*Assumptions!$G$15*Assumptions!$G$16 -> 10574904
B30: Feed total | C30: BDT | E30: =E28+E29 -> 5160084 | F30: =F28+F29 -> 15067721 | G30: =G28+G29 -> 19558720 | H30: =H28+H29 -> 20536657 | I30: =I28+I29 -> 21563489
B31: Broodstock: hatchery | C31: BDT | E31: =Hatchery!D42*Assumptions!$G$15 -> 145000 | F31: =Hatchery!G42*Assumptions!$G$15 -> 362500 | G31: =Hatchery!J42*Assumptions!$G$15 -> 580000 | H31: =Hatchery!M42*Assumptions!$G$15 -> 580000 | I31: =Hatchery!P42*Assumptions!$G$15 -> 580000
B32: Fingerlings: farming | C32: BDT | E32: =Farming!D49*Assumptions!$G$15 -> 780000 | F32: =Farming!G49*Assumptions!$G$15 -> 1170000 | G32: =Farming!J49*Assumptions!$G$15 -> 1170000 | H32: =Farming!M49*Assumptions!$G$15 -> 1170000 | I32: =Farming!P49*Assumptions!$G$15 -> 1170000
B33: Broodstock and fingerlings total | C33: BDT | E33: =E31+E32 -> 925000 | F33: =F31+F32 -> 1532500 | G33: =G31+G32 -> 1750000 | H33: =H31+H32 -> 1750000 | I33: =I31+I32 -> 1750000
B34: Hormone: hatchery | C34: BDT | E34: =Hatchery!D46*Assumptions!$G$15 -> 1600000 | F34: =Hatchery!G46*Assumptions!$G$15 -> 4000000 | G34: =Hatchery!J46*Assumptions!$G$15 -> 6400000 | H34: =Hatchery!M46*Assumptions!$G$15 -> 6400000 | I34: =Hatchery!P46*Assumptions!$G$15 -> 6400000
B35: Direct costs (feed, stock, hormone) | C35: BDT | E35: =E30+E33+E34 -> 7685084 | F35: =F30+F33+F34 -> 20600221 | G35: =G30+G33+G34 -> 27708720 | H35: =H30+H33+H34 -> 28686657 | I35: =I30+I33+I34 -> 29713489
B36: Factory overheads (fuel, lime, utilities, packing, labour) | C36: BDT | E36: =E64*Assumptions!$G$15 -> 996250 | F36: =F64*Assumptions!$G$15 -> 1962125 | G36: =G64*Assumptions!$G$15 -> 2067381.2 | H36: =H64*Assumptions!$G$15 -> 2178615.3 | I36: =I64*Assumptions!$G$15 -> 2296197.6
B37: Marketing (% of hatchery revenue) | C37: BDT | E37: =Assumptions!$D$61*E12 -> 188000 | F37: =Assumptions!$D$61*F12 -> 537600 | G37: =Assumptions!$D$61*G12 -> 856642.5 | H37: =Assumptions!$D$61*H12 -> 1157625 | I37: =Assumptions!$D$61*I12 -> 982129.05
B38: Selling (% of hatchery revenue) | C38: BDT | E38: =Assumptions!$D$62*E12 -> 752000 | F38: =Assumptions!$D$62*F12 -> 2150400 | G38: =Assumptions!$D$62*G12 -> 3426570 | H38: =Assumptions!$D$62*H12 -> 4630500 | I38: =Assumptions!$D$62*I12 -> 3928516.2
B39: Total variable costs | C39: BDT | E39: =E35+E36+E37+E38 -> 9621334 | F39: =F35+F36+F37+F38 -> 25250346 | G39: =G35+G36+G37+G38 -> 34059314 | H39: =H35+H36+H37+H38 -> 36653397 | I39: =I35+I36+I37+I38 -> 36920332
B40: Contribution (revenue less variable costs) | C40: BDT | E40: =E16-E39 -> 2458666 | F40: =F16-F39 -> 24467154 | G40: =G16-G39 -> 32752186 | H40: =H16-H39 -> 46406197 | I40: =I16-I39 -> 38623381
B41: Contribution margin | C41: % | E41: =IFERROR(E40/E16,0) -> 0.20353195 | F41: =IFERROR(F40/F16,0) -> 0.49212359 | G41: =IFERROR(G40/G16,0) -> 0.49021779 | H41: =IFERROR(H40/H16,0) -> 0.55870965 | I41: =IFERROR(I40/I16,0) -> 0.51127194
B43: D. Fixed costs (BDT thousand): they do not change with production
B44: Salaries and festival bonus | C44: BDT | E44: =E67+E68+E69+E70 -> 936000 | F44: =F67+F68+F69+F70 -> 1392300 | G44: =G67+G68+G69+G70 -> 1461915 | H44: =H67+H68+H69+H70 -> 1535010.8 | I44: =I67+I68+I69+I70 -> 1611761.3
...

Sheet Working Capital
B1: Working Capital and Cash Cycle
B2: Receivables, inventory and payables are driven by days.
B3: ="Scenario: "&Assumptions!$D$11&" | BDT '000 unless stated" -> Scenario: Base case | BDT '000 unless stated
B4: Financial year | C4: Unit | D4: Opening | E4: ="FY"&(Assumptions!$D$7+E5-1)&"-"&TEXT(MOD(Assumptions!$D$7+E5,100),"00") -> FY2026-27 | F4: ="FY"&(Assumptions!$D$7+F5-1)&"-"&TEXT(MOD(Assumptions!$D$7+F5,100),"00") -> FY2027-28 | G4: ="FY"&(Assumptions!$D$7+G5-1)&"-"&TEXT(MOD(Assumptions!$D$7+G5,100),"00") -> FY2028-29 | H4: ="FY"&(Assumptions!$D$7+H5-1)&"-"&TEXT(MOD(Assumptions!$D$7+H5,100),"00") -> FY2029-30 | I4: ="FY"&(Assumptions!$D$7+I5-1)&"-"&TEXT(MOD(Assumptions!$D$7+I5,100),"00") -> FY2030-31
D5: 0 | E5: 1 | F5: 2 | G5: 3 | H5: 4 | I5: 5
B7: Base for the calculation
B8: Revenue | C8: BDT | E8: =Operations!E16 -> 12080000 | F8: =Operations!F16 -> 49717500 | G8: =Operations!G16 -> 66811500 | H8: =Operations!H16 -> 83059594 | I8: =Operations!I16 -> 75543713
B9: Cost of sales (direct costs and factory overheads) | C9: BDT | E9: =Operations!E35+Operations!E36 -> 8681334 | F9: =Operations!F35+Operations!F36 -> 22562346 | G9: =Operations!G35+Operations!G36 -> 29776102 | H9: =Operations!H35+Operations!H36 -> 30865272 | I9: =Operations!I35+Operations!I36 -> 32009687
B11: Working capital balances
B12: Trade receivables | C12: BDT | D12: 0 | E12: =E8*Assumptions!$D$64/365 -> 992876.71 | F12: =F8*Assumptions!$D$64/365 -> 4086369.9 | G12: =G8*Assumptions!$D$64/365 -> 5491356.2 | H12: =H8*Assumptions!$D$64/365 -> 6826815.9 | I12: =I8*Assumptions!$D$64/365 -> 6209072.3
B13: Inventory (feed, fingerlings, stock on hand) | C13: BDT | D13: 0 | E13: =E9*Assumptions!$D$65/365 -> 2140602.9 | F13: =F9*Assumptions!$D$65/365 -> 5563318.1 | G13: =G9*Assumptions!$D$65/365 -> 7342052.5 | H13: =H9*Assumptions!$D$65/365 -> 7610615 | I13: =I9*Assumptions!$D$65/365 -> 7892799.5
B14: Trade payables | C14: BDT | D14: 0 | E14: =E9*Assumptions!$D$66/365 -> 713534.3 | F14: =F9*Assumptions!$D$66/365 -> 1854439.4 | G14: =G9*Assumptions!$D$66/365 -> 2447350.8 | H14: =H9*Assumptions!$D$66/365 -> 2536871.7 | I14: =I9*Assumptions!$D$66/365 -> 2630933.2
B15: Net working capital | C15: BDT | D15: =D12+D13-D14 -> 0 | E15: =E12+E13-E14 -> 2419945.3 | F15: =F12+F13-F14 -> 7795248.6 | G15: =G12+G13-G14 -> 10386058 | H15: =H12+H13-H14 -> 11900559 | I15: =I12+I13-I14 -> 11470939
B16: Increase in net working capital (cash outflow) | C16: BDT | E16: =E15-D15 -> 2419945.3 | F16: =F15-E15 -> 5375303.3 | G16: =G15-F15 -> 2590809.2 | H16: =H15-G15 -> 1514501.4 | I16: =I15-H15 -> -429620.56
B17: Net working capital as % of revenue | C17: % | E17: =IFERROR(E15/E8,0) -> 0.2003266 | F17: =IFERROR(F15/F8,0) -> 0.15679084 | G17: =IFERROR(G15/G8,0) -> 0.15545315 | H17: =IFERROR(H15/H8,0) -> 0.14327736 | I17: =IFERROR(I15/I8,0) -> 0.15184505
B19: Cash conversion cycle (days)
B20: Receivable days (DSO) | C20: days | E20: =Assumptions!$D$64 -> 30 | F20: =Assumptions!$D$64 -> 30 | G20: =Assumptions!$D$64 -> 30 | H20: =Assumptions!$D$64 -> 30 | I20: =Assumptions!$D$64 -> 30
B21: Inventory days (DIO) | C21: days | E21: =Assumptions!$D$65 -> 90 | F21: =Assumptions!$D$65 -> 90 | G21: =Assumptions!$D$65 -> 90 | H21: =Assumptions!$D$65 -> 90 | I21: =Assumptions!$D$65 -> 90
B22: Operating cycle (DSO + DIO) | C22: days | E22: =E20+E21 -> 120 | F22: =F20+F21 -> 120 | G22: =G20+G21 -> 120 | H22: =H20+H21 -> 120 | I22: =I20+I21 -> 120
B23: Payable days (DPO) | C23: days | E23: =Assumptions!$D$66 -> 30 | F23: =Assumptions!$D$66 -> 30 | G23: =Assumptions!$D$66 -> 30 | H23: =Assumptions!$D$66 -> 30 | I23: =Assumptions!$D$66 -> 30
B24: Cash conversion cycle (DSO + DIO - DPO) | C24: days | E24: =E22-E23 -> 90 | F24: =F22-F23 -> 90 | G24: =G22-G23 -> 90 | H24: =H22-H23 -> 90 | I24: =I22-I23 -> 90
B28: Chart data (Year 4)
B29: DSO | D29: =H20 -> 30
B30: DIO | D30: =H21 -> 90
B31: DPO | D31: =H23 -> 30
B32: Cycle | D32: =H24 -> 90

Sheet Funding
B1: Funding and Term Loan
B2: Sources and uses of funds at Year 0, the owner contribution and the bank loan schedule.
B3: ="Scenario: "&Assumptions!$D$11&" | BDT '000 unless stated" -> Scenario: Base case | BDT '000 unless stated
B4: Financial year | C4: Unit | D4: Opening | E4: ="FY"&(Assumptions!$D$7+E5-1)&"-"&TEXT(MOD(Assumptions!$D$7+E5,100),"00") -> FY2026-27 | F4: ="FY"&(Assumptions!$D$7+F5-1)&"-"&TEXT(MOD(Assumptions!$D$7+F5,100),"00") -> FY2027-28 | G4: ="FY"&(Assumptions!$D$7+G5-1)&"-"&TEXT(MOD(Assumptions!$D$7+G5,100),"00") -> FY2028-29 | H4: ="FY"&(Assumptions!$D$7+H5-1)&"-"&TEXT(MOD(Assumptions!$D$7+H5,100),"00") -> FY2029-30 | I4: ="FY"&(Assumptions!$D$7+I5-1)&"-"&TEXT(MOD(Assumptions!$D$7+I5,100),"00") -> FY2030-31
D5: 0 | E5: 1 | F5: 2 | G5: 3 | H5: 4 | I5: 5
B7: Uses of funds (Year 0)
B8: Land and ponds | C8: BDT | D8: ='FA Schedule'!D8+'FA Schedule'!D9 -> 20915783
B9: Buildings and overhead tank | C9: BDT | D9: ='FA Schedule'!D10+'FA Schedule'!D11 -> 19764147
B10: Equipment, vehicles, furniture and fixtures | C10: BDT | D10: ='FA Schedule'!D12+'FA Schedule'!D13+'FA Schedule'!D14 -> 5112312.5
B11: Fixed assets (project cost) | C11: BDT | D11: =SUM(D8:D10) -> 45792242
B12: Opening cash for Year 1 working capital | C12: BDT | D12: ='Working Capital'!E15 -> 2419945.3
B13: Total uses | C13: BDT | D13: =D11+D12 -> 48212188
B15: Sources of funds (Year 0)
B16: Bank term loan | C16: BDT | D16: =Assumptions!$D$41*D11 -> 22896121
B17: Owner equity | C17: BDT | D17: =D13-D16 -> 25316066
B18: Total sources | C18: BDT | D18: =D16+D17 -> 48212188
B19: Bank loan as % of total uses | C19: % | D19: =D16/D18 -> 0.47490318
B20: Owner contribution as % of total uses | C20: % | D20: =D17/D18 -> 0.52509682
B22: Financial year | C22: Unit | D22: Opening | E22: ="FY"&(Assumptions!$D$7+E23-1)&"-"&TEXT(MOD(Assumptions!$D$7+E23,100),"00") -> FY2026-27 | F22: ="FY"&(Assumptions!$D$7+F23-1)&"-"&TEXT(MOD(Assumptions!$D$7+F23,100),"00") -> FY2027-28 | G22: ="FY"&(Assumptions!$D$7+G23-1)&"-"&TEXT(MOD(Assumptions!$D$7+G23,100),"00") -> FY2028-29 | H22: ="FY"&(Assumptions!$D$7+H23-1)&"-"&TEXT(MOD(Assumptions!$D$7+H23,100),"00") -> FY2029-30 | I22: ="FY"&(Assumptions!$D$7+I23-1)&"-"&TEXT(MOD(Assumptions!$D$7+I23,100),"00") -> FY2030-31
D23: 0 | E23: 1 | F23: 2 | G23: 3 | H23: 4 | I23: 5
B24: Term loan schedule
B25: Repayment share of the loan | C25: % | E25: =IF(AND(E$23>Assumptions!$D$43,E$23<=Assumptions!$D$42),1/(Assumptions!$D$42-Assumptions!$D$43),0) -> 0 | F25: =IF(AND(F$23>Assumptions!$D$43,F$23<=Assumptions!$D$42),1/(Assumptions!$D$42-Assumptions!$D$43),0) -> 0.25 | G25: =IF(AND(G$23>Assumptions!$D$43,G$23<=Assumptions!$D$42),1/(Assumptions!$D$42-Assumptions!$D$43),0) -> 0.25 | H25: =IF(AND(H$23>Assumptions!$D$43,H$23<=Assumptions!$D$42),1/(Assumptions!$D$42-Assumptions!$D$43),0) -> 0.25 | I25: =IF(AND(I$23>Assumptions!$D$43,I$23<=Assumptions!$D$42),1/(Assumptions!$D$42-Assumptions!$D$43),0) -> 0.25
B26: Opening balance | C26: BDT | E26: =D29 -> 22896121 | F26: =E29 -> 22896121 | G26: =F29 -> 17172091 | H26: =G29 -> 11448061 | I26: =H29 -> 5724030.3
B27: Drawdown | C27: BDT | D27: =D16 -> 22896121
B28: Repayment | C28: BDT | E28: =E25*$D16 -> 0 | F28: =F25*$D16 -> 5724030.3 | G28: =G25*$D16 -> 5724030.3 | H28: =H25*$D16 -> 5724030.3 | I28: =I25*$D16 -> 5724030.3
B29: Closing balance | C29: BDT | D29: =D27 -> 22896121 | E29: =E26+E27-E28 -> 22896121 | F29: =F26+F27-F28 -> 17172091 | G29: =G26+G27-G28 -> 11448061 | H29: =H26+H27-H28 -> 5724030.3 | I29: =I26+I27-I28 -> 0
B31: Interest rate (loan rate plus scenario add-on) | C31: % | E31: =Assumptions!$D$40+Assumptions!$G$18 -> 0.12 | F31: =Assumptions!$D$40+Assumptions!$G$18 -> 0.12 | G31: =Assumptions!$D$40+Assumptions!$G$18 -> 0.12 | H31: =Assumptions!$D$40+Assumptions!$G$18 -> 0.12 | I31: =Assumptions!$D$40+Assumptions!$G$18 -> 0.12
B32: Interest (on opening balance) | C32: BDT | E32: =E26*E31 -> 2747534.5 | F32: =F26*F31 -> 2747534.5 | G32: =G26*G31 -> 2060650.9 | H32: =H26*H31 -> 1373767.3 | I32: =I26*I31 -> 686883.63
B33: Total debt service (interest + repayment) | C33: BDT | E33: =E32+E28 -> 2747534.5 | F33: =F32+F28 -> 8471564.8 | G33: =G32+G28 -> 7784681.2 | H33: =H32+H28 -> 7097797.5 | I33: =I32+I28 -> 6410913.9
B35: Interest on opening balance. The loan funds fixed assets only; the owner funds the rest.

Sheet Income Statement
B1: Projected Income Statement
B2: Farming and hatchery revenue and costs, with depreciation shown below EBITDA and interest on the bank loan. Costs are negative.
B3: ="Scenario: "&Assumptions!$D$11&" | BDT '000 unless stated" -> Scenario: Base case | BDT '000 unless stated
B4: Financial year | C4: Unit | D4: Opening | E4: ="FY"&(Assumptions!$D$7+E5-1)&"-"&TEXT(MOD(Assumptions!$D$7+E5,100),"00") -> FY2026-27 | F4: ="FY"&(Assumptions!$D$7+F5-1)&"-"&TEXT(MOD(Assumptions!$D$7+F5,100),"00") -> FY2027-28 | G4: ="FY"&(Assumptions!$D$7+G5-1)&"-"&TEXT(MOD(Assumptions!$D$7+G5,100),"00") -> FY2028-29 | H4: ="FY"&(Assumptions!$D$7+H5-1)&"-"&TEXT(MOD(Assumptions!$D$7+H5,100),"00") -> FY2029-30 | I4: ="FY"&(Assumptions!$D$7+I5-1)&"-"&TEXT(MOD(Assumptions!$D$7+I5,100),"00") -> FY2030-31
D5: 0 | E5: 1 | F5: 2 | G5: 3 | H5: 4 | I5: 5
B7: Revenue
B8: Hatchery | C8: BDT | E8: =Operations!E12 -> 9400000 | F8: =Operations!F12 -> 26880000 | G8: =Operations!G12 -> 42832125 | H8: =Operations!H12 -> 57881250 | I8: =Operations!I12 -> 49106453
B9: Farming | C9: BDT | E9: =Operations!E15 -> 2680000 | F9: =Operations!F15 -> 22837500 | G9: =Operations!G15 -> 23979375 | H9: =Operations!H15 -> 25178344 | I9: =Operations!I15 -> 26437261
B10: Total revenue | C10: BDT | E10: =SUM(E8:E9) -> 12080000 | F10: =SUM(F8:F9) -> 49717500 | G10: =SUM(G8:G9) -> 66811500 | H10: =SUM(H8:H9) -> 83059594 | I10: =SUM(I8:I9) -> 75543713
B11: Revenue growth | C11: % | F11: =IFERROR(F10/E10-1,0) -> 3.1156871 | G11: =IFERROR(G10/F10-1,0) -> 0.3438226 | H11: =IFERROR(H10/G10-1,0) -> 0.24319307 | I11: =IFERROR(I10/H10-1,0) -> -0.090487805
B13: Cost of sales
B14: Feed | C14: BDT | E14: =-Operations!E30 -> -5160084 | F14: =-Operations!F30 -> -15067721 | G14: =-Operations!G30 -> -19558720 | H14: =-Operations!H30 -> -20536657 | I14: =-Operations!I30 -> -21563489
B15: Broodstock and fingerlings | C15: BDT | E15: =-Operations!E33 -> -925000 | F15: =-Operations!F33 -> -1532500 | G15: =-Operations!G33 -> -1750000 | H15: =-Operations!H33 -> -1750000 | I15: =-Operations!I33 -> -1750000
B16: Hormone | C16: BDT | E16: =-Operations!E34 -> -1600000 | F16: =-Operations!F34 -> -4000000 | G16: =-Operations!G34 -> -6400000 | H16: =-Operations!H34 -> -6400000 | I16: =-Operations!I34 -> -6400000
B17: Factory overheads | C17: BDT | E17: =-Operations!E36 -> -996250 | F17: =-Operations!F36 -> -1962125 | G17: =-Operations!G36 -> -2067381.2 | H17: =-Operations!H36 -> -2178615.3 | I17: =-Operations!I36 -> -2296197.6
B18: Total cost of sales | C18: BDT | E18: =SUM(E14:E17) -> -8681334 | F18: =SUM(F14:F17) -> -22562346 | G18: =SUM(G14:G17) -> -29776102 | H18: =SUM(H14:H17) -> -30865272 | I18: =SUM(I14:I17) -> -32009687
B19: Gross profit | C19: BDT | E19: =E10+E18 -> 3398666 | F19: =F10+F18 -> 27155154 | G19: =G10+G18 -> 37035398 | H19: =H10+H18 -> 52194322 | I19: =I10+I18 -> 43534027
B20: Gross margin | C20: % | E20: =IFERROR(E19/E10,0) -> 0.28134652 | F20: =IFERROR(F19/F10,0) -> 0.54618906 | G20: =IFERROR(G19/G10,0) -> 0.5543267 | H20: =IFERROR(H19/H10,0) -> 0.62839607 | I20: =IFERROR(I19/I10,0) -> 0.57627597
B22: Operating expenses
B23: Administrative | C23: BDT | E23: =-Operations!E46 -> -1166550 | F23: =-Operations!F46 -> -1855665 | G23: =-Operations!G46 -> -1957635.8 | H23: =-Operations!H46 -> -2066148.8 | I23: =-Operations!I46 -> -2181675.6
B24: Marketing | C24: BDT | E24: =-Operations!E37 -> -188000 | F24: =-Operations!F37 -> -537600 | G24: =-Operations!G37 -> -856642.5 | H24: =-Operations!H37 -> -1157625 | I24: =-Operations!I37 -> -982129.05
B25: Selling | C25: BDT | E25: =-Operations!E38 -> -752000 | F25: =-Operations!F38 -> -2150400 | G25: =-Operations!G38 -> -3426570 | H25: =-Operations!H38 -> -4630500 | I25: =-Operations!I38 -> -3928516.2
B26: Distribution | C26: BDT | E26: =-Operations!E47 -> -500000 | F26: =-Operations!F47 -> -500000 | G26: =-Operations!G47 -> -500000 | H26: =-Operations!H47 -> -500000 | I26: =-Operations!I47 -> -500000
B27: Total operating expenses | C27: BDT | E27: =SUM(E23:E26) -> -2606550 | F27: =SUM(F23:F26) -> -5043665 | G27: =SUM(G23:G26) -> -6740848.2 | H27: =SUM(H23:H26) -> -8354273.8 | I27: =SUM(I23:I26) -> -7592320.9
B28: EBITDA | C28: BDT | E28: =E19+E27 -> 792115.99 | F28: =F19+F27 -> 22111489 | G28: =G19+G27 -> 30294550 | H28: =H19+H27 -> 43840048 | I28: =I19+I27 -> 35941706
B29: EBITDA margin | C29: % | E29: =IFERROR(E28/E10,0) -> 0.065572516 | F29: =IFERROR(F28/F10,0) -> 0.44474259 | G29: =IFERROR(G28/G10,0) -> 0.45343317 | H29: =IFERROR(H28/H10,0) -> 0.52781438 | I29: =IFERROR(I28/I10,0) -> 0.47577362
B30: Depreciation | C30: BDT | E30: =-'FA Schedule'!E24 -> -3098877.2 | F30: =-'FA Schedule'!F24 -> -3098877.2 | G30: =-'FA Schedule'!G24 -> -3298877.2 | H30: =-'FA Schedule'!H24 -> -3298877.2 | I30: =-'FA Schedule'!I24 -> -3298877.2
B31: EBIT | C31: BDT | E31: =E28+E30 -> -2306761.2 | F31: =F28+F30 -> 19012612 | G31: =G28+G30 -> 26995673 | H31: =H28+H30 -> 40541171 | I31: =I28+I30 -> 32642828
B32: Interest on term loan | C32: BDT | E32: =-Funding!E32 -> -2747534.5 | F32: =-Funding!F32 -> -2747534.5 | G32: =-Funding!G32 -> -2060650.9 | H32: =-Funding!H32 -> -1373767.3 | I32: =-Funding!I32 -> -686883.63
B33: Profit before tax | C33: BDT | E33: =E31+E32 -> -5054295.7 | F33: =F31+F32 -> 16265078 | G33: =G31+G32 -> 24935022 | H33: =H31+H32 -> 39167404 | I33: =I31+I32 -> 31955945
B34: Income tax | C34: BDT | E34: =-E43*Assumptions!$D$39 -> 0 | F34: =-F43*Assumptions!$D$39 -> -3082965.1 | G34: =-G43*Assumptions!$D$39 -> -6857131 | H34: =-H43*Assumptions!$D$39 -> -10771036 | I34: =-I43*Assumptions!$D$39 -> -8787884.8
B35: Net profit after tax | C35: BDT | E35: =E33+E34 -> -5054295.7 | F35: =F33+F34 -> 13182113 | G35: =G33+G34 -> 18077891 | H35: =H33+H34 -> 28396368 | I35: =I33+I34 -> 23168060
B36: Net margin | C36: % | E36: =IFERROR(E35/E10,0) -> -0.41840196 | F36: =IFERROR(F35/F10,0) -> 0.2651403 | G36: =IFERROR(G35/G10,0) -> 0.27058053 | H36: =IFERROR(H35/H10,0) -> 0.34187944 | I36: =IFERROR(I35/I10,0) -> 0.30668416
B38: Tax loss carried forward
B39: Tax loss, opening | C39: BDT | E39: 0 | F39: =E42 -> 5054295.7 | G39: =F42 -> 0 | H39: =G42 -> 0 | I39: =H42 -> 0
B40: Loss used against profit | C40: BDT | E40: =MIN(E39,MAX(E33,0)) -> 0 | F40: =MIN(F39,MAX(F33,0)) -> 5054295.7 | G40: =MIN(G39,MAX(G33,0)) -> 0 | H40: =MIN(H39,MAX(H33,0)) -> 0 | I40: =MIN(I39,MAX(I33,0)) -> 0
B41: Loss added | C41: BDT | E41: =MAX(-E33,0) -> 5054295.7 | F41: =MAX(-F33,0) -> 0 | G41: =MAX(-G33,0) -> 0 | H41: =MAX(-H33,0) -> 0 | I41: =MAX(-I33,0) -> 0
B42: Tax loss, closing | C42: BDT | E42: =E39-E40+E41 -> 5054295.7 | F42: =F39-F40+F41 -> 0 | G42: =G39-G40+G41 -> 0 | H42: =H39-H40+H41 -> 0 | I42: =I39-I40+I41 -> 0
B43: Taxable profit | C43: BDT | E43: =MAX(E33,0)-E40 -> 0 | F43: =MAX(F33,0)-F40 -> 11210782 | G43: =MAX(G33,0)-G40 -> 24935022 | H43: =MAX(H33,0)-H40 -> 39167404 | I43: =MAX(I33,0)-I40 -> 31955945

Sheet Cash Flow
B1: Projected Cash Flow Statement
B2: Indirect method. This single statement drives the balance sheet; owner funding and dividends are decided here.
B3: ="Scenario: "&Assumptions!$D$11&" | BDT '000 unless stated" -> Scenario: Base case | BDT '000 unless stated
B4: Financial year | C4: Unit | D4: Opening | E4: ="FY"&(Assumptions!$D$7+E5-1)&"-"&TEXT(MOD(Assumptions!$D$7+E5,100),"00") -> FY2026-27 | F4: ="FY"&(Assumptions!$D$7+F5-1)&"-"&TEXT(MOD(Assumptions!$D$7+F5,100),"00") -> FY2027-28 | G4: ="FY"&(Assumptions!$D$7+G5-1)&"-"&TEXT(MOD(Assumptions!$D$7+G5,100),"00") -> FY2028-29 | H4: ="FY"&(Assumptions!$D$7+H5-1)&"-"&TEXT(MOD(Assumptions!$D$7+H5,100),"00") -> FY2029-30 | I4: ="FY"&(Assumptions!$D$7+I5-1)&"-"&TEXT(MOD(Assumptions!$D$7+I5,100),"00") -> FY2030-31
D5: 0 | E5: 1 | F5: 2 | G5: 3 | H5: 4 | I5: 5
B7: Operating activities
B8: Net profit after tax | C8: BDT | E8: ='Income Statement'!E35 -> -5054295.7 | F8: ='Income Statement'!F35 -> 13182113 | G8: ='Income Statement'!G35 -> 18077891 | H8: ='Income Statement'!H35 -> 28396368 | I8: ='Income Statement'!I35 -> 23168060
B9: Add: depreciation | C9: BDT | E9: =-'Income Statement'!E30 -> 3098877.2 | F9: =-'Income Statement'!F30 -> 3098877.2 | G9: =-'Income Statement'!G30 -> 3298877.2 | H9: =-'Income Statement'!H30 -> 3298877.2 | I9: =-'Income Statement'!I30 -> 3298877.2
B10: Increase in receivables | C10: BDT | E10: =-('Working Capital'!E12-'Working Capital'!D12) -> -992876.71 | F10: =-('Working Capital'!F12-'Working Capital'!E12) -> -3093493.2 | G10: =-('Working Capital'!G12-'Working Capital'!F12) -> -1404986.3 | H10: =-('Working Capital'!H12-'Working Capital'!G12) -> -1335459.8 | I10: =-('Working Capital'!I12-'Working Capital'!H12) -> 617743.59
B11: Increase in inventory | C11: BDT | E11: =-('Working Capital'!E13-'Working Capital'!D13) -> -2140602.9 | F11: =-('Working Capital'!F13-'Working Capital'!E13) -> -3422715.2 | G11: =-('Working Capital'!G13-'Working Capital'!F13) -> -1778734.4 | H11: =-('Working Capital'!H13-'Working Capital'!G13) -> -268562.49 | I11: =-('Working Capital'!I13-'Working Capital'!H13) -> -282184.54
B12: Increase in payables | C12: BDT | E12: ='Working Capital'!E14-'Working Capital'!D14 -> 713534.3 | F12: ='Working Capital'!F14-'Working Capital'!E14 -> 1140905.1 | G12: ='Working Capital'!G14-'Working Capital'!F14 -> 592911.47 | H12: ='Working Capital'!H14-'Working Capital'!G14 -> 89520.829 | I12: ='Working Capital'!I14-'Working Capital'!H14 -> 94061.514
B13: Cash flow from operations | C13: BDT | E13: =SUM(E8:E12) -> -4375363.9 | F13: =SUM(F8:F12) -> 10905687 | G13: =SUM(G8:G12) -> 18785959 | H13: =SUM(H8:H12) -> 30180743 | I13: =SUM(I8:I12) -> 26896558
B15: Investing activities
B16: Capital expenditure | C16: BDT | D16: =-'FA Schedule'!D15 -> -45792242 | E16: =-'FA Schedule'!E15 -> 0 | F16: =-'FA Schedule'!F15 -> -5003000 | G16: =-'FA Schedule'!G15 -> 0 | H16: =-'FA Schedule'!H15 -> 0 | I16: =-'FA Schedule'!I15 -> 0
B17: Cash flow from investing | C17: BDT | D17: =D16 -> -45792242 | E17: =E16 -> 0 | F17: =F16 -> -5003000 | G17: =G16 -> 0 | H17: =H16 -> 0 | I17: =I16 -> 0
B19: Financing activities
B20: Term loan drawdown | C20: BDT | D20: =Funding!D27 -> 22896121 | E20: 0 | F20: 0 | G20: 0 | H20: 0 | I20: 0
B21: Term loan repayment | C21: BDT | E21: =-Funding!E28 -> 0 | F21: =-Funding!F28 -> -5724030.3 | G21: =-Funding!G28 -> -5724030.3 | H21: =-Funding!H28 -> -5724030.3 | I21: =-Funding!I28 -> -5724030.3
